Workbook

Sheet Smart Dashboard
A1: ⌂ | C1: STATUS GODOWN NO. 9, 14, 18 AND 20 | M1: ="Last Updated : "&TEXT(NOW(),"dd.mm.yy")&" | "&TEXT(NOW(),"HH:mm")&" ↻" | Q1: Stack Type | R1: Count | S1: Status | T1: Count | U1: Infested Rank | V1: Due Rank
C2: =COUNTIFS('Master Stock'!$D$2:$D$1000,"<>",'Master Stock'!$H$2:$H$1000,"OCCUPIED") | E2: =COUNTIFS('Master Stock'!$D$2:$D$1000,"<>",'Master Stock'!$H$2:$H$1000,"EMPTY") | G2: INFESTED / UNDER COVER | I2: FUMIGATION DUE | K2: QUICK NAVIGATION | Q2: Rice (FRK + RRA) | R2: =B11 | S2: Infested / Under Cover | T2: =G11 | U2: =IF(AND('Master Stock'!D2<>"",'Master Stock'!H2="OCCUPIED",ISNUMBER('Master Stock'!J2),'Master Stock'!K2=""),SUMPRODUCT(--('Master Stock'!$D$2:$D$1000<>""),--('Master Stock'!$H$2:$H$1000="OCCUPIED"),--ISNUMBER('Master Stock'!$J$2:$J$1000),--('Master Stock'!$K$2:$K$1000=""),--('Master Stock'!$J$2:$J$1000<'Master Stock'!J2))+COUNTIFS('Master Stock'!$J$2:J2,'Master Stock'!J2,'Master Stock'!$D$2:D2,"<>",'Master Stock'!$H$2:H2,"OCCUPIED",'Master Stock'!$K$2:K2,""),"") | V2: =IF(AND('Master Stock'!D2<>"",'Master Stock'!H2="OCCUPIED",ISNUMBER('Master Stock'!L2),'Master Stock'!L2<TODAY()-30),SUMPRODUCT(--('Master Stock'!$D$2:$D$1000<>""),--('Master Stock'!$H$2:$H$1000="OCCUPIED"),--ISNUMBER('Master Stock'!$L$2:$L$1000),--('Master Stock'!$L$2:$L$1000<TODAY()-30),--('Master Stock'!$L$2:$L$1000<'Master Stock'!L2))+COUNTIFS('Master Stock'!$L$2:L2,'Master Stock'!L2,'Master Stock'!$D$2:D2,"<>",'Master Stock'!$H$2:H2,"OCCUPIED"),"")
A3: =COUNTIF('Master Stock'!$D$2:$D$1000,"<>") | G3: =COUNTIFS('Master Stock'!$D$2:$D$1000,"<>",'Master Stock'!$H$2:$H$1000,"OCCUPIED",'Master Stock'!$J$2:$J$1000,"<>",'Master Stock'!$K$2:$K$1000,"") | I3: =COUNTIFS('Master Stock'!$D$2:$D$1000,"<>",'Master Stock'!$H$2:$H$1000,"OCCUPIED",'Master Stock'!$L$2:$L$1000,"<>",'Master Stock'!$L$2:$L$1000,"<"&TODAY()-30) | K3: ☷ QC DETAILS | Q3: Empty Stack | R3: =B12 | S3: Fumigation Due | T3: =G12 | U3: =IF(AND('Master Stock'!D3<>"",'Master Stock'!H3="OCCUPIED",ISNUMBER('Master Stock'!J3),'Master Stock'!K3=""),SUMPRODUCT(--('Master Stock'!$D$2:$D$1000<>""),--('Master Stock'!$H$2:$H$1000="OCCUPIED"),--ISNUMBER('Master Stock'!$J$2:$J$1000),--('Master Stock'!$K$2:$K$1000=""),--('Master Stock'!$J$2:$J$1000<'Master Stock'!J3))+COUNTIFS('Master Stock'!$J$2:J3,'Master Stock'!J3,'Master Stock'!$D$2:D3,"<>",'Master Stock'!$H$2:H3,"OCCUPIED",'Master Stock'!$K$2:K3,""),"") | V3: =IF(AND('Master Stock'!D3<>"",'Master Stock'!H3="OCCUPIED",ISNUMBER('Master Stock'!L3),'Master Stock'!L3<TODAY()-30),SUMPRODUCT(--('Master Stock'!$D$2:$D$1000<>""),--('Master Stock'!$H$2:$H$1000="OCCUPIED"),--ISNUMBER('Master Stock'!$L$2:$L$1000),--('Master Stock'!$L$2:$L$1000<TODAY()-30),--('Master Stock'!$L$2:$L$1000<'Master Stock'!L3))+COUNTIFS('Master Stock'!$L$2:L3,'Master Stock'!L3,'Master Stock'!$D$2:D3,"<>",'Master Stock'!$H$2:H3,"OCCUPIED"),"")
U4: =IF(AND('Master Stock'!D4<>"",'Master Stock'!H4="OCCUPIED",ISNUMBER('Master Stock'!J4),'Master Stock'!K4=""),SUMPRODUCT(--('Master Stock'!$D$2:$D$1000<>""),--('Master Stock'!$H$2:$H$1000="OCCUPIED"),--ISNUMBER('Master Stock'!$J$2:$J$1000),--('Master Stock'!$K$2:$K$1000=""),--('Master Stock'!$J$2:$J$1000<'Master Stock'!J4))+COUNTIFS('Master Stock'!$J$2:J4,'Master Stock'!J4,'Master Stock'!$D$2:D4,"<>",'Master Stock'!$H$2:H4,"OCCUPIED",'Master Stock'!$K$2:K4,""),"") | V4: =IF(AND('Master Stock'!D4<>"",'Master Stock'!H4="OCCUPIED",ISNUMBER('Master Stock'!L4),'Master Stock'!L4<TODAY()-30),SUMPRODUCT(--('Master Stock'!$D$2:$D$1000<>""),--('Master Stock'!$H$2:$H$1000="OCCUPIED"),--ISNUMBER('Master Stock'!$L$2:$L$1000),--('Master Stock'!$L$2:$L$1000<TODAY()-30),--('Master Stock'!$L$2:$L$1000<'Master Stock'!L4))+COUNTIFS('Master Stock'!$L$2:L4,'Master Stock'!L4,'Master Stock'!$D$2:D4,"<>",'Master Stock'!$H$2:H4,"OCCUPIED"),"")
C5: Full Stacks | E5: Empty Stacks | K5: ▤ MASTER | U5: =IF(AND('Master Stock'!D5<>"",'Master Stock'!H5="OCCUPIED",ISNUMBER('Master Stock'!J5),'Master Stock'!K5=""),SUMPRODUCT(--('Master Stock'!$D$2:$D$1000<>""),--('Master Stock'!$H$2:$H$1000="OCCUPIED"),--ISNUMBER('Master Stock'!$J$2:$J$1000),--('Master Stock'!$K$2:$K$1000=""),--('Master Stock'!$J$2:$J$1000<'Master Stock'!J5))+COUNTIFS('Master Stock'!$J$2:J5,'Master Stock'!J5,'Master Stock'!$D$2:D5,"<>",'Master Stock'!$H$2:H5,"OCCUPIED",'Master Stock'!$K$2:K5,""),"") | V5: =IF(AND('Master Stock'!D5<>"",'Master Stock'!H5="OCCUPIED",ISNUMBER('Master Stock'!L5),'Master Stock'!L5<TODAY()-30),SUMPRODUCT(--('Master Stock'!$D$2:$D$1000<>""),--('Master Stock'!$H$2:$H$1000="OCCUPIED"),--ISNUMBER('Master Stock'!$L$2:$L$1000),--('Master Stock'!$L$2:$L$1000<TODAY()-30),--('Master Stock'!$L$2:$L$1000<'Master Stock'!L5))+COUNTIFS('Master Stock'!$L$2:L5,'Master Stock'!L5,'Master Stock'!$D$2:D5,"<>",'Master Stock'!$H$2:H5,"OCCUPIED"),"")
A6: All Stacks | G6: Requires Attention | I6: Due for Fumigation | U6: =IF(AND('Master Stock'!D6<>"",'Master Stock'!H6="OCCUPIED",ISNUMBER('Master Stock'!J6),'Master Stock'!K6=""),SUMPRODUCT(--('Master Stock'!$D$2:$D$1000<>""),--('Master Stock'!$H$2:$H$1000="OCCUPIED"),--ISNUMBER('Master Stock'!$J$2:$J$1000),--('Master Stock'!$K$2:$K$1000=""),--('Master Stock'!$J$2:$J$1000<'Master Stock'!J6))+COUNTIFS('Master Stock'!$J$2:J6,'Master Stock'!J6,'Master Stock'!$D$2:D6,"<>",'Master Stock'!$H$2:H6,"OCCUPIED",'Master Stock'!$K$2:K6,""),"") | V6: =IF(AND('Master Stock'!D6<>"",'Master Stock'!H6="OCCUPIED",ISNUMBER('Master Stock'!L6),'Master Stock'!L6<TODAY()-30),SUMPRODUCT(--('Master Stock'!$D$2:$D$1000<>""),--('Master Stock'!$H$2:$H$1000="OCCUPIED"),--ISNUMBER('Master Stock'!$L$2:$L$1000),--('Master Stock'!$L$2:$L$1000<TODAY()-30),--('Master Stock'!$L$2:$L$1000<'Master Stock'!L6))+COUNTIFS('Master Stock'!$L$2:L6,'Master Stock'!L6,'Master Stock'!$D$2:D6,"<>",'Master Stock'!$H$2:H6,"OCCUPIED"),"")
K7: 🌾 RICE PRIORITY | U7: =IF(AND('Master Stock'!D7<>"",'Master Stock'!H7="OCCUPIED",ISNUMBER('Master Stock'!J7),'Master Stock'!K7=""),SUMPRODUCT(--('Master Stock'!$D$2:$D$1000<>""),--('Master Stock'!$H$2:$H$1000="OCCUPIED"),--ISNUMBER('Master Stock'!$J$2:$J$1000),--('Master Stock'!$K$2:$K$1000=""),--('Master Stock'!$J$2:$J$1000<'Master Stock'!J7))+COUNTIFS('Master Stock'!$J$2:J7,'Master Stock'!J7,'Master Stock'!$D$2:D7,"<>",'Master Stock'!$H$2:H7,"OCCUPIED",'Master Stock'!$K$2:K7,""),"") | V7: =IF(AND('Master Stock'!D7<>"",'Master Stock'!H7="OCCUPIED",ISNUMBER('Master Stock'!L7),'Master Stock'!L7<TODAY()-30),SUMPRODUCT(--('Master Stock'!$D$2:$D$1000<>""),--('Master Stock'!$H$2:$H$1000="OCCUPIED"),--ISNUMBER('Master Stock'!$L$2:$L$1000),--('Master Stock'!$L$2:$L$1000<TODAY()-30),--('Master Stock'!$L$2:$L$1000<'Master Stock'!L7))+COUNTIFS('Master Stock'!$L$2:L7,'Master Stock'!L7,'Master Stock'!$D$2:D7,"<>",'Master Stock'!$H$2:H7,"OCCUPIED"),"")
A8: STACK TYPE SUMMARY | C8: STACK MIX | F8: INFESTATION STATUS | H8: INFESTATION STATUS | U8: =IF(AND('Master Stock'!D8<>"",'Master Stock'!H8="OCCUPIED",ISNUMBER('Master Stock'!J8),'Master Stock'!K8=""),SUMPRODUCT(--('Master Stock'!$D$2:$D$1000<>""),--('Master Stock'!$H$2:$H$1000="OCCUPIED"),--ISNUMBER('Master Stock'!$J$2:$J$1000),--('Master Stock'!$K$2:$K$1000=""),--('Master Stock'!$J$2:$J$1000<'Master Stock'!J8))+COUNTIFS('Master Stock'!$J$2:J8,'Master Stock'!J8,'Master Stock'!$D$2:D8,"<>",'Master Stock'!$H$2:H8,"OCCUPIED",'Master Stock'!$K$2:K8,""),"") | V8: =IF(AND('Master Stock'!D8<>"",'Master Stock'!H8="OCCUPIED",ISNUMBER('Master Stock'!L8),'Master Stock'!L8<TODAY()-30),SUMPRODUCT(--('Master Stock'!$D$2:$D$1000<>""),--('Master Stock'!$H$2:$H$1000="OCCUPIED"),--ISNUMBER('Master Stock'!$L$2:$L$1000),--('Master Stock'!$L$2:$L$1000<TODAY()-30),--('Master Stock'!$L$2:$L$1000<'Master Stock'!L8))+COUNTIFS('Master Stock'!$L$2:L8,'Master Stock'!L8,'Master Stock'!$D$2:D8,"<>",'Master Stock'!$H$2:H8,"OCCUPIED"),"")
A9: STACK TYPE | B9: COUNT | F9: STATUS | G9: COUNT | K9: 🌾 WHEAT PRIORITY | U9: =IF(AND('Master Stock'!D9<>"",'Master Stock'!H9="OCCUPIED",ISNUMBER('Master Stock'!J9),'Master Stock'!K9=""),SUMPRODUCT(--('Master Stock'!$D$2:$D$1000<>""),--('Master Stock'!$H$2:$H$1000="OCCUPIED"),--ISNUMBER('Master Stock'!$J$2:$J$1000),--('Master Stock'!$K$2:$K$1000=""),--('Master Stock'!$J$2:$J$1000<'Master Stock'!J9))+COUNTIFS('Master Stock'!$J$2:J9,'Master Stock'!J9,'Master Stock'!$D$2:D9,"<>",'Master Stock'!$H$2:H9,"OCCUPIED",'Master Stock'!$K$2:K9,""),"") | V9: =IF(AND('Master Stock'!D9<>"",'Master Stock'!H9="OCCUPIED",ISNUMBER('Master Stock'!L9),'Master Stock'!L9<TODAY()-30),SUMPRODUCT(--('Master Stock'!$D$2:$D$1000<>""),--('Master Stock'!$H$2:$H$1000="OCCUPIED"),--ISNUMBER('Master Stock'!$L$2:$L$1000),--('Master Stock'!$L$2:$L$1000<TODAY()-30),--('Master Stock'!$L$2:$L$1000<'Master Stock'!L9))+COUNTIFS('Master Stock'!$L$2:L9,'Master Stock'!L9,'Master Stock'!$D$2:D9,"<>",'Master Stock'!$H$2:H9,"OCCUPIED"),"")
A10: Wheat | B10: =COUNTIFS('Master Stock'!$D$2:$D$1000,"<>",'Master Stock'!$G$2:$G$1000,"*WHEAT*") | F10: Clear | G10: =MAX(0,$C$2-$G$3) | U10: =IF(AND('Master Stock'!D10<>"",'Master Stock'!H10="OCCUPIED",ISNUMBER('Master Stock'!J10),'Master Stock'!K10=""),SUMPRODUCT(--('Master Stock'!$D$2:$D$1000<>""),--('Master Stock'!$H$2:$H$1000="OCCUPIED"),--ISNUMBER('Master Stock'!$J$2:$J$1000),--('Master Stock'!$K$2:$K$1000=""),--('Master Stock'!$J$2:$J$1000<'Master Stock'!J10))+COUNTIFS('Master Stock'!$J$2:J10,'Master Stock'!J10,'Master Stock'!$D$2:D10,"<>",'Master Stock'!$H$2:H10,"OCCUPIED",'Master Stock'!$K$2:K10,""),"") | V10: =IF(AND('Master Stock'!D10<>"",'Master Stock'!H10="OCCUPIED",ISNUMBER('Master Stock'!L10),'Master Stock'!L10<TODAY()-30),SUMPRODUCT(--('Master Stock'!$D$2:$D$1000<>""),--('Master Stock'!$H$2:$H$1000="OCCUPIED"),--ISNUMBER('Master Stock'!$L$2:$L$1000),--('Master Stock'!$L$2:$L$1000<TODAY()-30),--('Master Stock'!$L$2:$L$1000<'Master Stock'!L10))+COUNTIFS('Master Stock'!$L$2:L10,'Master Stock'!L10,'Master Stock'!$D$2:D10,"<>",'Master Stock'!$H$2:H10,"OCCUPIED"),"")
A11: Rice (FRK + RRA) | B11: =COUNTIFS('Master Stock'!$D$2:$D$1000,"<>",'Master Stock'!$G$2:$G$1000,"*FRK*",'Master Stock'!$G$2:$G$1000,"*RRA*") | F11: Infested / Under Cover | G11: =$G$3 | U11: =IF(AND('Master Stock'!D11<>"",'Master Stock'!H11="OCCUPIED",ISNUMBER('Master Stock'!J11),'Master Stock'!K11=""),SUMPRODUCT(--('Master Stock'!$D$2:$D$1000<>""),--('Master Stock'!$H$2:$H$1000="OCCUPIED"),--ISNUMBER('Master Stock'!$J$2:$J$1000),--('Master Stock'!$K$2:$K$1000=""),--('Master Stock'!$J$2:$J$1000<'Master Stock'!J11))+COUNTIFS('Master Stock'!$J$2:J11,'Master Stock'!J11,'Master Stock'!$D$2:D11,"<>",'Master Stock'!$H$2:H11,"OCCUPIED",'Master Stock'!$K$2:K11,""),"") | V11: =IF(AND('Master Stock'!D11<>"",'Master Stock'!H11="OCCUPIED",ISNUMBER('Master Stock'!L11),'Master Stock'!L11<TODAY()-30),SUMPRODUCT(--('Master Stock'!$D$2:$D$1000<>""),--('Master Stock'!$H$2:$H$1000="OCCUPIED"),--ISNUMBER('Master Stock'!$L$2:$L$1000),--('Master Stock'!$L$2:$L$1000<TODAY()-30),--('Master Stock'!$L$2:$L$1000<'Master Stock'!L11))+COUNTIFS('Master Stock'!$L$2:L11,'Master Stock'!L11,'Master Stock'!$D$2:D11,"<>",'Master Stock'!$H$2:H11,"OCCUPIED"),"")
A12: Empty Stack | B12: =COUNTIFS('Master Stock'!$D$2:$D$1000,"<>",'Master Stock'!$H$2:$H$1000,"EMPTY") | F12: Fumigation Due | G12: =$I$3 | K12: SEARCH STACK | U12: =IF(AND('Master Stock'!D12<>"",'Master Stock'!H12="OCCUPIED",ISNUMBER('Master Stock'!J12),'Master Stock'!K12=""),SUMPRODUCT(--('Master Stock'!$D$2:$D$1000<>""),--('Master Stock'!$H$2:$H$1000="OCCUPIED"),--ISNUMBER('Master Stock'!$J$2:$J$1000),--('Master Stock'!$K$2:$K$1000=""),--('Master Stock'!$J$2:$J$1000<'Master Stock'!J12))+COUNTIFS('Master Stock'!$J$2:J12,'Master Stock'!J12,'Master Stock'!$D$2:D12,"<>",'Master Stock'!$H$2:H12,"OCCUPIED",'Master Stock'!$K$2:K12,""),"") | V12: =IF(AND('Master Stock'!D12<>"",'Master Stock'!H12="OCCUPIED",ISNUMBER('Master Stock'!L12),'Master Stock'!L12<TODAY()-30),SUMPRODUCT(--('Master Stock'!$D$2:$D$1000<>""),--('Master Stock'!$H$2:$H$1000="OCCUPIED"),--ISNUMBER('Master Stock'!$L$2:$L$1000),--('Master Stock'!$L$2:$L$1000<TODAY()-30),--('Master Stock'!$L$2:$L$1000<'Master Stock'!L12))+COUNTIFS('Master Stock'!$L$2:L12,'Master Stock'!L12,'Master Stock'!$D$2:D12,"<>",'Master Stock'!$H$2:H12,"OCCUPIED"),"")
A13: TOTAL | B13: =SUM(B10:B12) | K13: 14A02 | U13: =IF(AND('Master Stock'!D13<>"",'Master Stock'!H13="OCCUPIED",ISNUMBER('Master Stock'!J13),'Master Stock'!K13=""),SUMPRODUCT(--('Master Stock'!$D$2:$D$1000<>""),--('Master Stock'!$H$2:$H$1000="OCCUPIED"),--ISNUMBER('Master Stock'!$J$2:$J$1000),--('Master Stock'!$K$2:$K$1000=""),--('Master Stock'!$J$2:$J$1000<'Master Stock'!J13))+COUNTIFS('Master Stock'!$J$2:J13,'Master Stock'!J13,'Master Stock'!$D$2:D13,"<>",'Master Stock'!$H$2:H13,"OCCUPIED",'Master Stock'!$K$2:K13,""),"") | V13: =IF(AND('Master Stock'!D13<>"",'Master Stock'!H13="OCCUPIED",ISNUMBER('Master Stock'!L13),'Master Stock'!L13<TODAY()-30),SUMPRODUCT(--('Master Stock'!$D$2:$D$1000<>""),--('Master Stock'!$H$2:$H$1000="OCCUPIED"),--ISNUMBER('Master Stock'!$L$2:$L$1000),--('Master Stock'!$L$2:$L$1000<TODAY()-30),--('Master Stock'!$L$2:$L$1000<'Master Stock'!L13))+COUNTIFS('Master Stock'!$L$2:L13,'Master Stock'!L13,'Master Stock'!$D$2:D13,"<>",'Master Stock'!$H$2:H13,"OCCUPIED"),"")
U14: =IF(AND('Master Stock'!D14<>"",'Master Stock'!H14="OCCUPIED",ISNUMBER('Master Stock'!J14),'Master Stock'!K14=""),SUMPRODUCT(--('Master Stock'!$D$2:$D$1000<>""),--('Master Stock'!$H$2:$H$1000="OCCUPIED"),--ISNUMBER('Master Stock'!$J$2:$J$1000),--('Master Stock'!$K$2:$K$1000=""),--('Master Stock'!$J$2:$J$1000<'Master Stock'!J14))+COUNTIFS('Master Stock'!$J$2:J14,'Master Stock'!J14,'Master Stock'!$D$2:D14,"<>",'Master Stock'!$H$2:H14,"OCCUPIED",'Master Stock'!$K$2:K14,""),"") | V14: =IF(AND('Master Stock'!D14<>"",'Master Stock'!H14="OCCUPIED",ISNUMBER('Master Stock'!L14),'Master Stock'!L14<TODAY()-30),SUMPRODUCT(--('Master Stock'!$D$2:$D$1000<>""),--('Master Stock'!$H$2:$H$1000="OCCUPIED"),--ISNUMBER('Master Stock'!$L$2:$L$1000),--('Master Stock'!$L$2:$L$1000<TODAY()-30),--('Master Stock'!$L$2:$L$1000<'Master Stock'!L14))+COUNTIFS('Master Stock'!$L$2:L14,'Master Stock'!L14,'Master Stock'!$D$2:D14,"<>",'Master Stock'!$H$2:H14,"OCCUPIED"),"")
U15: =IF(AND('Master Stock'!D15<>"",'Master Stock'!H15="OCCUPIED",ISNUMBER('Master Stock'!J15),'Master Stock'!K15=""),SUMPRODUCT(--('Master Stock'!$D$2:$D$1000<>""),--('Master Stock'!$H$2:$H$1000="OCCUPIED"),--ISNUMBER('Master Stock'!$J$2:$J$1000),--('Master Stock'!$K$2:$K$1000=""),--('Master Stock'!$J$2:$J$1000<'Master Stock'!J15))+COUNTIFS('Master Stock'!$J$2:J15,'Master Stock'!J15,'Master Stock'!$D$2:D15,"<>",'Master Stock'!$H$2:H15,"OCCUPIED",'Master Stock'!$K$2:K15,""),"") | V15: =IF(AND('Master Stock'!D15<>"",'Master Stock'!H15="OCCUPIED",ISNUMBER('Master Stock'!L15),'Master Stock'!L15<TODAY()-30),SUMPRODUCT(--('Master Stock'!$D$2:$D$1000<>""),--('Master Stock'!$H$2:$H$1000="OCCUPIED"),--ISNUMBER('Master Stock'!$L$2:$L$1000),--('Master Stock'!$L$2:$L$1000<TODAY()-30),--('Master Stock'!$L$2:$L$1000<'Master Stock'!L15))+COUNTIFS('Master Stock'!$L$2:L15,'Master Stock'!L15,'Master Stock'!$D$2:D15,"<>",'Master Stock'!$H$2:H15,"OCCUPIED"),"")
K16: Stack No. | L16: {=IF($K$13="","",IFERROR(INDEX('Master Stock'!$D$2:$D$1000,MATCH($K$13,'Master Stock'!$D$2:$D$1000,0)),""))} | U16: =IF(AND('Master Stock'!D16<>"",'Master Stock'!H16="OCCUPIED",ISNUMBER('Master Stock'!J16),'Master Stock'!K16=""),SUMPRODUCT(--('Master Stock'!$D$2:$D$1000<>""),--('Master Stock'!$H$2:$H$1000="OCCUPIED"),--ISNUMBER('Master Stock'!$J$2:$J$1000),--('Master Stock'!$K$2:$K$1000=""),--('Master Stock'!$J$2:$J$1000<'Master Stock'!J16))+COUNTIFS('Master Stock'!$J$2:J16,'Master Stock'!J16,'Master Stock'!$D$2:D16,"<>",'Master Stock'!$H$2:H16,"OCCUPIED",'Master Stock'!$K$2:K16,""),"") | V16: =IF(AND('Master Stock'!D16<>"",'Master Stock'!H16="OCCUPIED",ISNUMBER('Master Stock'!L16),'Master Stock'!L16<TODAY()-30),SUMPRODUCT(--('Master Stock'!$D$2:$D$1000<>""),--('Master Stock'!$H$2:$H$1000="OCCUPIED"),--ISNUMBER('Master Stock'!$L$2:$L$1000),--('Master Stock'!$L$2:$L$1000<TODAY()-30),--('Master Stock'!$L$2:$L$1000<'Master Stock'!L16))+COUNTIFS('Master Stock'!$L$2:L16,'Master Stock'!L16,'Master Stock'!$D$2:D16,"<>",'Master Stock'!$H$2:H16,"OCCUPIED"),"")
K17: Commodity | L17: {=IF($K$13="","",IFERROR(INDEX('Master Stock'!$G$2:$G$1000,MATCH($K$13,'Master Stock'!$D$2:$D$1000,0)),""))} | U17: =IF(AND('Master Stock'!D17<>"",'Master Stock'!H17="OCCUPIED",ISNUMBER('Master Stock'!J17),'Master Stock'!K17=""),SUMPRODUCT(--('Master Stock'!$D$2:$D$1000<>""),--('Master Stock'!$H$2:$H$1000="OCCUPIED"),--ISNUMBER('Master Stock'!$J$2:$J$1000),--('Master Stock'!$K$2:$K$1000=""),--('Master Stock'!$J$2:$J$1000<'Master Stock'!J17))+COUNTIFS('Master Stock'!$J$2:J17,'Master Stock'!J17,'Master Stock'!$D$2:D17,"<>",'Master Stock'!$H$2:H17,"OCCUPIED",'Master Stock'!$K$2:K17,""),"") | V17: =IF(AND('Master Stock'!D17<>"",'Master Stock'!H17="OCCUPIED",ISNUMBER('Master Stock'!L17),'Master Stock'!L17<TODAY()-30),SUMPRODUCT(--('Master Stock'!$D$2:$D$1000<>""),--('Master Stock'!$H$2:$H$1000="OCCUPIED"),--ISNUMBER('Master Stock'!$L$2:$L$1000),--('Master Stock'!$L$2:$L$1000<TODAY()-30),--('Master Stock'!$L$2:$L$1000<'Master Stock'!L17))+COUNTIFS('Master Stock'!$L$2:L17,'Master Stock'!L17,'Master Stock'!$D$2:D17,"<>",'Master Stock'!$H$2:H17,"OCCUPIED"),"")
K18: Date of Receipt | L18: {=IF($K$13="","",IFERROR(INDEX('Master Stock'!$B$2:$B$1000,MATCH($K$13,'Master Stock'!$D$2:$D$1000,0)),""))} | U18: =IF(AND('Master Stock'!D18<>"",'Master Stock'!H18="OCCUPIED",ISNUMBER('Master Stock'!J18),'Master Stock'!K18=""),SUMPRODUCT(--('Master Stock'!$D$2:$D$1000<>""),--('Master Stock'!$H$2:$H$1000="OCCUPIED"),--ISNUMBER('Master Stock'!$J$2:$J$1000),--('Master Stock'!$K$2:$K$1000=""),--('Master Stock'!$J$2:$J$1000<'Master Stock'!J18))+COUNTIFS('Master Stock'!$J$2:J18,'Master Stock'!J18,'Master Stock'!$D$2:D18,"<>",'Master Stock'!$H$2:H18,"OCCUPIED",'Master Stock'!$K$2:K18,""),"") | V18: =IF(AND('Master Stock'!D18<>"",'Master Stock'!H18="OCCUPIED",ISNUMBER('Master Stock'!L18),'Master Stock'!L18<TODAY()-30),SUMPRODUCT(--('Master Stock'!$D$2:$D$1000<>""),--('Master Stock'!$H$2:$H$1000="OCCUPIED"),--ISNUMBER('Master Stock'!$L$2:$L$1000),--('Master Stock'!$L$2:$L$1000<TODAY()-30),--('Master Stock'!$L$2:$L$1000<'Master Stock'!L18))+COUNTIFS('Master Stock'!$L$2:L18,'Master Stock'!L18,'Master Stock'!$D$2:D18,"<>",'Master Stock'!$H$2:H18,"OCCUPIED"),"")
A19: 🐞 INFESTED / UNDER COVER DETAILS | E19: 🧯 FUMIGATION DUE DETAILS | K19: Last Fumigation | L19: {=IF($K$13="","",IFERROR(INDEX('Master Stock'!$L$2:$L$1000,MATCH($K$13,'Master Stock'!$D$2:$D$1000,0)),""))} | U19: =IF(AND('Master Stock'!D19<>"",'Master Stock'!H19="OCCUPIED",ISNUMBER('Master Stock'!J19),'Master Stock'!K19=""),SUMPRODUCT(--('Master Stock'!$D$2:$D$1000<>""),--('Master Stock'!$H$2:$H$1000="OCCUPIED"),--ISNUMBER('Master Stock'!$J$2:$J$1000),--('Master Stock'!$K$2:$K$1000=""),--('Master Stock'!$J$2:$J$1000<'Master Stock'!J19))+COUNTIFS('Master Stock'!$J$2:J19,'Master Stock'!J19,'Master Stock'!$D$2:D19,"<>",'Master Stock'!$H$2:H19,"OCCUPIED",'Master Stock'!$K$2:K19,""),"") | V19: =IF(AND('Master Stock'!D19<>"",'Master Stock'!H19="OCCUPIED",ISNUMBER('Master Stock'!L19),'Master Stock'!L19<TODAY()-30),SUMPRODUCT(--('Master Stock'!$D$2:$D$1000<>""),--('Master Stock'!$H$2:$H$1000="OCCUPIED"),--ISNUMBER('Master Stock'!$L$2:$L$1000),--('Master Stock'!$L$2:$L$1000<TODAY()-30),--('Master Stock'!$L$2:$L$1000<'Master Stock'!L19))+COUNTIFS('Master Stock'!$L$2:L19,'Master Stock'!L19,'Master Stock'!$D$2:D19,"<>",'Master Stock'!$H$2:H19,"OCCUPIED"),"")
A20: Stack No. | B20: Commodity | C20: Fumigation Date | D20: Days | E20: Stack No. | F20: Commodity | G20: Last Fumigation | H20: Days | K20: Fumigation Days | L20: =IF(L19="","",MAX(0,TODAY()-L19)) | U20: =IF(AND('Master Stock'!D20<>"",'Master Stock'!H20="OCCUPIED",ISNUMBER('Master Stock'!J20),'Master Stock'!K20=""),SUMPRODUCT(--('Master Stock'!$D$2:$D$1000<>""),--('Master Stock'!$H$2:$H$1000="OCCUPIED"),--ISNUMBER('Master Stock'!$J$2:$J$1000),--('Master Stock'!$K$2:$K$1000=""),--('Master Stock'!$J$2:$J$1000<'Master Stock'!J20))+COUNTIFS('Master Stock'!$J$2:J20,'Master Stock'!J20,'Master Stock'!$D$2:D20,"<>",'Master Stock'!$H$2:H20,"OCCUPIED",'Master Stock'!$K$2:K20,""),"") | V20: =IF(AND('Master Stock'!D20<>"",'Master Stock'!H20="OCCUPIED",ISNUMBER('Master Stock'!L20),'Master Stock'!L20<TODAY()-30),SUMPRODUCT(--('Master Stock'!$D$2:$D$1000<>""),--('Master Stock'!$H$2:$H$1000="OCCUPIED"),--ISNUMBER('Master Stock'!$L$2:$L$1000),--('Master Stock'!$L$2:$L$1000<TODAY()-30),--('Master Stock'!$L$2:$L$1000<'Master Stock'!L20))+COUNTIFS('Master Stock'!$L$2:L20,'Master Stock'!L20,'Master Stock'!$D$2:D20,"<>",'Master Stock'!$H$2:H20,"OCCUPIED"),"")
A21: {=IFERROR(INDEX('Master Stock'!$D$2:$D$1000,MATCH(1,$U$2:$U$999,0)),"")} | B21: {=IFERROR(INDEX('Master Stock'!$G$2:$G$1000,MATCH(1,$U$2:$U$999,0)),"")} | C21: {=IFERROR(INDEX('Master Stock'!$J$2:$J$1000,MATCH(1,$U$2:$U$999,0)),"")} | D21: =IF(C21="","",MAX(0,TODAY()-C21)) | E21: {=IFERROR(INDEX('Master Stock'!$D$2:$D$1000,MATCH(1,$V$2:$V$999,0)),"")} | F21: {=IFERROR(INDEX('Master Stock'!$G$2:$G$1000,MATCH(1,$V$2:$V$999,0)),"")} | G21: {=IFERROR(INDEX('Master Stock'!$L$2:$L$1000,MATCH(1,$V$2:$V$999,0)),"")} | H21: =IF(G21="","",MAX(0,TODAY()-G21)) | K21: Status | L21: {=IF(L16="","",IF(AND(INDEX('Master Stock'!$J$2:$J$1000,MATCH($K$13,'Master Stock'!$D$2:$D$1000,0))<>"",INDEX('Master Stock'!$K$2:$K$1000,MATCH($K$13,'Master Stock'!$D$2:$D$1000,0))=""),"INFESTED / UNDER COVER",IF(AND(L19<>"",L20>30),"FUMIGATION DUE","CLEAR")))} | U21: =IF(AND('Master Stock'!D21<>"",'Master Stock'!H21="OCCUPIED",ISNUMBER('Master Stock'!J21),'Master Stock'!K21=""),SUMPRODUCT(--('Master Stock'!$D$2:$D$1000<>""),--('Master Stock'!$H$2:$H$1000="OCCUPIED"),--ISNUMBER('Master Stock'!$J$2:$J$1000),--('Master Stock'!$K$2:$K$1000=""),--('Master Stock'!$J$2:$J$1000<'Master Stock'!J21))+COUNTIFS('Master Stock'!$J$2:J21,'Master Stock'!J21,'Master Stock'!$D$2:D21,"<>",'Master Stock'!$H$2:H21,"OCCUPIED",'Master Stock'!$K$2:K21,""),"") | V21: =IF(AND('Master Stock'!D21<>"",'Master Stock'!H21="OCCUPIED",ISNUMBER('Master Stock'!L21),'Master Stock'!L21<TODAY()-30),SUMPRODUCT(--('Master Stock'!$D$2:$D$1000<>""),--('Master Stock'!$H$2:$H$1000="OCCUPIED"),--ISNUMBER('Master Stock'!$L$2:$L$1000),--('Master Stock'!$L$2:$L$1000<TODAY()-30),--('Master Stock'!$L$2:$L$1000<'Master Stock'!L21))+COUNTIFS('Master Stock'!$L$2:L21,'Master Stock'!L21,'Master Stock'!$D$2:D21,"<>",'Master Stock'!$H$2:H21,"OCCUPIED"),"")
A22: {=IFERROR(INDEX('Master Stock'!$D$2:$D$1000,MATCH(2,$U$2:$U$999,0)),"")} | B22: {=IFERROR(INDEX('Master Stock'!$G$2:$G$1000,MATCH(2,$U$2:$U$999,0)),"")} | C22: {=IFERROR(INDEX('Master Stock'!$J$2:$J$1000,MATCH(2,$U$2:$U$999,0)),"")} | D22: =IF(C22="","",MAX(0,TODAY()-C22)) | E22: {=IFERROR(INDEX('Master Stock'!$D$2:$D$1000,MATCH(2,$V$2:$V$999,0)),"")} | F22: {=IFERROR(INDEX('Master Stock'!$G$2:$G$1000,MATCH(2,$V$2:$V$999,0)),"")} | G22: {=IFERROR(INDEX('Master Stock'!$L$2:$L$1000,MATCH(2,$V$2:$V$999,0)),"")} | H22: =IF(G22="","",MAX(0,TODAY()-G22)) | U22: =IF(AND('Master Stock'!D22<>"",'Master Stock'!H22="OCCUPIED",ISNUMBER('Master Stock'!J22),'Master Stock'!K22=""),SUMPRODUCT(--('Master Stock'!$D$2:$D$1000<>""),--('Master Stock'!$H$2:$H$1000="OCCUPIED"),--ISNUMBER('Master Stock'!$J$2:$J$1000),--('Master Stock'!$K$2:$K$1000=""),--('Master Stock'!$J$2:$J$1000<'Master Stock'!J22))+COUNTIFS('Master Stock'!$J$2:J22,'Master Stock'!J22,'Master Stock'!$D$2:D22,"<>",'Master Stock'!$H$2:H22,"OCCUPIED",'Master Stock'!$K$2:K22,""),"") | V22: =IF(AND('Master Stock'!D22<>"",'Master Stock'!H22="OCCUPIED",ISNUMBER('Master Stock'!L22),'Master Stock'!L22<TODAY()-30),SUMPRODUCT(--('Master Stock'!$D$2:$D$1000<>""),--('Master Stock'!$H$2:$H$1000="OCCUPIED"),--ISNUMBER('Master Stock'!$L$2:$L$1000),--('Master Stock'!$L$2:$L$1000<TODAY()-30),--('Master Stock'!$L$2:$L$1000<'Master Stock'!L22))+COUNTIFS('Master Stock'!$L$2:L22,'Master Stock'!L22,'Master Stock'!$D$2:D22,"<>",'Master Stock'!$H$2:H22,"OCCUPIED"),"")
A23: {=IFERROR(INDEX('Master Stock'!$D$2:$D$1000,MATCH(3,$U$2:$U$999,0)),"")} | B23: {=IFERROR(INDEX('Master Stock'!$G$2:$G$1000,MATCH(3,$U$2:$U$999,0)),"")} | C23: {=IFERROR(INDEX('Master Stock'!$J$2:$J$1000,MATCH(3,$U$2:$U$999,0)),"")} | D23: =IF(C23="","",MAX(0,TODAY()-C23)) | E23: {=IFERROR(INDEX('Master Stock'!$D$2:$D$1000,MATCH(3,$V$2:$V$999,0)),"")} | F23: {=IFERROR(INDEX('Master Stock'!$G$2:$G$1000,MATCH(3,$V$2:$V$999,0)),"")} | G23: {=IFERROR(INDEX('Master Stock'!$L$2:$L$1000,MATCH(3,$V$2:$V$999,0)),"")} | H23: =IF(G23="","",MAX(0,TODAY()-G23)) | U23: =IF(AND('Master Stock'!D23<>"",'Master Stock'!H23="OCCUPIED",ISNUMBER('Master Stock'!J23),'Master Stock'!K23=""),SUMPRODUCT(--('Master Stock'!$D$2:$D$1000<>""),--('Master Stock'!$H$2:$H$1000="OCCUPIED"),--ISNUMBER('Master Stock'!$J$2:$J$1000),--('Master Stock'!$K$2:$K$1000=""),--('Master Stock'!$J$2:$J$1000<'Master Stock'!J23))+COUNTIFS('Master Stock'!$J$2:J23,'Master Stock'!J23,'Master Stock'!$D$2:D23,"<>",'Master Stock'!$H$2:H23,"OCCUPIED",'Master Stock'!$K$2:K23,""),"") | V23: =IF(AND('Master Stock'!D23<>"",'Master Stock'!H23="OCCUPIED",ISNUMBER('Master Stock'!L23),'Master Stock'!L23<TODAY()-30),SUMPRODUCT(--('Master Stock'!$D$2:$D$1000<>""),--('Master Stock'!$H$2:$H$1000="OCCUPIED"),--ISNUMBER('Master Stock'!$L$2:$L$1000),--('Master Stock'!$L$2:$L$1000<TODAY()-30),--('Master Stock'!$L$2:$L$1000<'Master Stock'!L23))+COUNTIFS('Master Stock'!$L$2:L23,'Master Stock'!L23,'Master Stock'!$D$2:D23,"<>",'Master Stock'!$H$2:H23,"OCCUPIED"),"")
A24: {=IFERROR(INDEX('Master Stock'!$D$2:$D$1000,MATCH(4,$U$2:$U$999,0)),"")} | B24: {=IFERROR(INDEX('Master Stock'!$G$2:$G$1000,MATCH(4,$U$2:$U$999,0)),"")} | C24: {=IFERROR(INDEX('Master Stock'!$J$2:$J$1000,MATCH(4,$U$2:$U$999,0)),"")} | D24: =IF(C24="","",MAX(0,TODAY()-C24)) | E24: {=IFERROR(INDEX('Master Stock'!$D$2:$D$1000,MATCH(4,$V$2:$V$999,0)),"")} | F24: {=IFERROR(INDEX('Master Stock'!$G$2:$G$1000,MATCH(4,$V$2:$V$999,0)),"")} | G24: {=IFERROR(INDEX('Master Stock'!$L$2:$L$1000,MATCH(4,$V$2:$V$999,0)),"")} | H24: =IF(G24="","",MAX(0,TODAY()-G24)) | U24: =IF(AND('Master Stock'!D24<>"",'Master Stock'!H24="OCCUPIED",ISNUMBER('Master Stock'!J24),'Master Stock'!K24=""),SUMPRODUCT(--('Master Stock'!$D$2:$D$1000<>""),--('Master Stock'!$H$2:$H$1000="OCCUPIED"),--ISNUMBER('Master Stock'!$J$2:$J$1000),--('Master Stock'!$K$2:$K$1000=""),--('Master Stock'!$J$2:$J$1000<'Master Stock'!J24))+COUNTIFS('Master Stock'!$J$2:J24,'Master Stock'!J24,'Master Stock'!$D$2:D24,"<>",'Master Stock'!$H$2:H24,"OCCUPIED",'Master Stock'!$K$2:K24,""),"") | V24: =IF(AND('Master Stock'!D24<>"",'Master Stock'!H24="OCCUPIED",ISNUMBER('Master Stock'!L24),'Master Stock'!L24<TODAY()-30),SUMPRODUCT(--('Master Stock'!$D$2:$D$1000<>""),--('Master Stock'!$H$2:$H$1000="OCCUPIED"),--ISNUMBER('Master Stock'!$L$2:$L$1000),--('Master Stock'!$L$2:$L$1000<TODAY()-30),--('Master Stock'!$L$2:$L$1000<'Master Stock'!L24))+COUNTIFS('Master Stock'!$L$2:L24,'Master Stock'!L24,'Master Stock'!$D$2:D24,"<>",'Master Stock'!$H$2:H24,"OCCUPIED"),"")
A25: {=IFERROR(INDEX('Master Stock'!$D$2:$D$1000,MATCH(5,$U$2:$U$999,0)),"")} | B25: {=IFERROR(INDEX('Master Stock'!$G$2:$G$1000,MATCH(5,$U$2:$U$999,0)),"")} | C25: {=IFERROR(INDEX('Master Stock'!$J$2:$J$1000,MATCH(5,$U$2:$U$999,0)),"")} | D25: =IF(C25="","",MAX(0,TODAY()-C25)) | E25: {=IFERROR(INDEX('Master Stock'!$D$2:$D$1000,MATCH(5,$V$2:$V$999,0)),"")} | F25: {=IFERROR(INDEX('Master Stock'!$G$2:$G$1000,MATCH(5,$V$2:$V$999,0)),"")} | G25: {=IFERROR(INDEX('Master Stock'!$L$2:$L$1000,MATCH(5,$V$2:$V$999,0)),"")} | H25: =IF(G25="","",MAX(0,TODAY()-G25)) | U25: =IF(AND('Master Stock'!D25<>"",'Master Stock'!H25="OCCUPIED",ISNUMBER('Master Stock'!J25),'Master Stock'!K25=""),SUMPRODUCT(--('Master Stock'!$D$2:$D$1000<>""),--('Master Stock'!$H$2:$H$1000="OCCUPIED"),--ISNUMBER('Master Stock'!$J$2:$J$1000),--('Master Stock'!$K$2:$K$1000=""),--('Master Stock'!$J$2:$J$1000<'Master Stock'!J25))+COUNTIFS('Master Stock'!$J$2:J25,'Master Stock'!J25,'Master Stock'!$D$2:D25,"<>",'Master Stock'!$H$2:H25,"OCCUPIED",'Master Stock'!$K$2:K25,""),"") | V25: =IF(AND('Master Stock'!D25<>"",'Master Stock'!H25="OCCUPIED",ISNUMBER('Master Stock'!L25),'Master Stock'!L25<TODAY()-30),SUMPRODUCT(--('Master Stock'!$D$2:$D$1000<>""),--('Master Stock'!$H$2:$H$1000="OCCUPIED"),--ISNUMBER('Master Stock'!$L$2:$L$1000),--('Master Stock'!$L$2:$L$1000<TODAY()-30),--('Master Stock'!$L$2:$L$1000<'Master Stock'!L25))+COUNTIFS('Master Stock'!$L$2:L25,'Master Stock'!L25,'Master Stock'!$D$2:D25,"<>",'Master Stock'!$H$2:H25,"OCCUPIED"),"")
A26: {=IFERROR(INDEX('Master Stock'!$D$2:$D$1000,MATCH(6,$U$2:$U$999,0)),"")} | B26: {=IFERROR(INDEX('Master Stock'!$G$2:$G$1000,MATCH(6,$U$2:$U$999,0)),"")} | C26: {=IFERROR(INDEX('Master Stock'!$J$2:$J$1000,MATCH(6,$U$2:$U$999,0)),"")} | D26: =IF(C26="","",MAX(0,TODAY()-C26)) | E26: {=IFERROR(INDEX('Master Stock'!$D$2:$D$1000,MATCH(6,$V$2:$V$999,0)),"")} | F26: {=IFERROR(INDEX('Master Stock'!$G$2:$G$1000,MATCH(6,$V$2:$V$999,0)),"")} | G26: {=IFERROR(INDEX('Master Stock'!$L$2:$L$1000,MATCH(6,$V$2:$V$999,0)),"")} | H26: =IF(G26="","",MAX(0,TODAY()-G26)) | U26: =IF(AND('Master Stock'!D26<>"",'Master Stock'!H26="OCCUPIED",ISNUMBER('Master Stock'!J26),'Master Stock'!K26=""),SUMPRODUCT(--('Master Stock'!$D$2:$D$1000<>""),--('Master Stock'!$H$2:$H$1000="OCCUPIED"),--ISNUMBER('Master Stock'!$J$2:$J$1000),--('Master Stock'!$K$2:$K$1000=""),--('Master Stock'!$J$2:$J$1000<'Master Stock'!J26))+COUNTIFS('Master Stock'!$J$2:J26,'Master Stock'!J26,'Master Stock'!$D$2:D26,"<>",'Master Stock'!$H$2:H26,"OCCUPIED",'Master Stock'!$K$2:K26,""),"") | V26: =IF(AND('Master Stock'!D26<>"",'Master Stock'!H26="OCCUPIED",ISNUMBER('Master Stock'!L26),'Master Stock'!L26<TODAY()-30),SUMPRODUCT(--('Master Stock'!$D$2:$D$1000<>""),--('Master Stock'!$H$2:$H$1000="OCCUPIED"),--ISNUMBER('Master Stock'!$L$2:$L$1000),--('Master Stock'!$L$2:$L$1000<TODAY()-30),--('Master Stock'!$L$2:$L$1000<'Master Stock'!L26))+COUNTIFS('Master Stock'!$L$2:L26,'Master Stock'!L26,'Master Stock'!$D$2:D26,"<>",'Master Stock'!$H$2:H26,"OCCUPIED"),"")
A27: {=IFERROR(INDEX('Master Stock'!$D$2:$D$1000,MATCH(7,$U$2:$U$999,0)),"")} | B27: {=IFERROR(INDEX('Master Stock'!$G$2:$G$1000,MATCH(7,$U$2:$U$999,0)),"")} | C27: {=IFERROR(INDEX('Master Stock'!$J$2:$J$1000,MATCH(7,$U$2:$U$999,0)),"")} | D27: =IF(C27="","",MAX(0,TODAY()-C27)) | E27: {=IFERROR(INDEX('Master Stock'!$D$2:$D$1000,MATCH(7,$V$2:$V$999,0)),"")} | F27: {=IFERROR(INDEX('Master Stock'!$G$2:$G$1000,MATCH(7,$V$2:$V$999,0)),"")} | G27: {=IFERROR(INDEX('Master Stock'!$L$2:$L$1000,MATCH(7,$V$2:$V$999,0)),"")} | H27: =IF(G27="","",MAX(0,TODAY()-G27)) | U27: =IF(AND('Master Stock'!D27<>"",'Master Stock'!H27="OCCUPIED",ISNUMBER('Master Stock'!J27),'Master Stock'!K27=""),SUMPRODUCT(--('Master Stock'!$D$2:$D$1000<>""),--('Master Stock'!$H$2:$H$1000="OCCUPIED"),--ISNUMBER('Master Stock'!$J$2:$J$1000),--('Master Stock'!$K$2:$K$1000=""),--('Master Stock'!$J$2:$J$1000<'Master Stock'!J27))+COUNTIFS('Master Stock'!$J$2:J27,'Master Stock'!J27,'Master Stock'!$D$2:D27,"<>",'Master Stock'!$H$2:H27,"OCCUPIED",'Master Stock'!$K$2:K27,""),"") | V27: =IF(AND('Master Stock'!D27<>"",'Master Stock'!H27="OCCUPIED",ISNUMBER('Master Stock'!L27),'Master Stock'!L27<TODAY()-30),SUMPRODUCT(--('Master Stock'!$D$2:$D$1000<>""),--('Master Stock'!$H$2:$H$1000="OCCUPIED"),--ISNUMBER('Master Stock'!$L$2:$L$1000),--('Master Stock'!$L$2:$L$1000<TODAY()-30),--('Master Stock'!$L$2:$L$1000<'Master Stock'!L27))+COUNTIFS('Master Stock'!$L$2:L27,'Master Stock'!L27,'Master Stock'!$D$2:D27,"<>",'Master Stock'!$H$2:H27,"OCCUPIED"),"")
A28: {=IFERROR(INDEX('Master Stock'!$D$2:$D$1000,MATCH(8,$U$2:$U$999,0)),"")} | B28: {=IFERROR(INDEX('Master Stock'!$G$2:$G$1000,MATCH(8,$U$2:$U$999,0)),"")} | C28: {=IFERROR(INDEX('Master Stock'!$J$2:$J$1000,MATCH(8,$U$2:$U$999,0)),"")} | D28: =IF(C28="","",MAX(0,TODAY()-C28)) | E28: {=IFERROR(INDEX('Master Stock'!$D$2:$D$1000,MATCH(8,$V$2:$V$999,0)),"")} | F28: {=IFERROR(INDEX('Master Stock'!$G$2:$G$1000,MATCH(8,$V$2:$V$999,0)),"")} | G28: {=IFERROR(INDEX('Master Stock'!$L$2:$L$1000,MATCH(8,$V$2:$V$999,0)),"")} | H28: =IF(G28="","",MAX(0,TODAY()-G28)) | U28: =IF(AND('Master Stock'!D28<>"",'Master Stock'!H28="OCCUPIED",ISNUMBER('Master Stock'!J28),'Master Stock'!K28=""),SUMPRODUCT(--('Master Stock'!$D$2:$D$1000<>""),--('Master Stock'!$H$2:$H$1000="OCCUPIED"),--ISNUMBER('Master Stock'!$J$2:$J$1000),--('Master Stock'!$K$2:$K$1000=""),--('Master Stock'!$J$2:$J$1000<'Master Stock'!J28))+COUNTIFS('Master Stock'!$J$2:J28,'Master Stock'!J28,'Master Stock'!$D$2:D28,"<>",'Master Stock'!$H$2:H28,"OCCUPIED",'Master Stock'!$K$2:K28,""),"") | V28: =IF(AND('Master Stock'!D28<>"",'Master Stock'!H28="OCCUPIED",ISNUMBER('Master Stock'!L28),'Master Stock'!L28<TODAY()-30),SUMPRODUCT(--('Master Stock'!$D$2:$D$1000<>""),--('Master Stock'!$H$2:$H$1000="OCCUPIED"),--ISNUMBER('Master Stock'!$L$2:$L$1000),--('Master Stock'!$L$2:$L$1000<TODAY()-30),--('Master Stock'!$L$2:$L$1000<'Master Stock'!L28))+COUNTIFS('Master Stock'!$L$2:L28,'Master Stock'!L28,'Master Stock'!$D$2:D28,"<>",'Master Stock'!$H$2:H28,"OCCUPIED"),"")
A29: {=IFERROR(INDEX('Master Stock'!$D$2:$D$1000,MATCH(9,$U$2:$U$999,0)),"")} | B29: {=IFERROR(INDEX('Master Stock'!$G$2:$G$1000,MATCH(9,$U$2:$U$999,0)),"")} | C29: {=IFERROR(INDEX('Master Stock'!$J$2:$J$1000,MATCH(9,$U$2:$U$999,0)),"")} | D29: =IF(C29="","",MAX(0,TODAY()-C29)) | E29: {=IFERROR(INDEX('Master Stock'!$D$2:$D$1000,MATCH(9,$V$2:$V$999,0)),"")} | F29: {=IFERROR(INDEX('Master Stock'!$G$2:$G$1000,MATCH(9,$V$2:$V$999,0)),"")} | G29: {=IFERROR(INDEX('Master Stock'!$L$2:$L$1000,MATCH(9,$V$2:$V$999,0)),"")} | H29: =IF(G29="","",MAX(0,TODAY()-G29)) | U29: =IF(AND('Master Stock'!D29<>"",'Master Stock'!H29="OCCUPIED",ISNUMBER('Master Stock'!J29),'Master Stock'!K29=""),SUMPRODUCT(--('Master Stock'!$D$2:$D$1000<>""),--('Master Stock'!$H$2:$H$1000="OCCUPIED"),--ISNUMBER('Master Stock'!$J$2:$J$1000),--('Master Stock'!$K$2:$K$1000=""),--('Master Stock'!$J$2:$J$1000<'Master Stock'!J29))+COUNTIFS('Master Stock'!$J$2:J29,'Master Stock'!J29,'Master Stock'!$D$2:D29,"<>",'Master Stock'!$H$2:H29,"OCCUPIED",'Master Stock'!$K$2:K29,""),"") | V29: =IF(AND('Master Stock'!D29<>"",'Master Stock'!H29="OCCUPIED",ISNUMBER('Master Stock'!L29),'Master Stock'!L29<TODAY()-30),SUMPRODUCT(--('Master Stock'!$D$2:$D$1000<>""),--('Master Stock'!$H$2:$H$1000="OCCUPIED"),--ISNUMBER('Master Stock'!$L$2:$L$1000),--('Master Stock'!$L$2:$L$1000<TODAY()-30),--('Master Stock'!$L$2:$L$1000<'Master Stock'!L29))+COUNTIFS('Master Stock'!$L$2:L29,'Master Stock'!L29,'Master Stock'!$D$2:D29,"<>",'Master Stock'!$H$2:H29,"OCCUPIED"),"")
A30: {=IFERROR(INDEX('Master Stock'!$D$2:$D$1000,MATCH(10,$U$2:$U$999,0)),"")} | B30: {=IFERROR(INDEX('Master Stock'!$G$2:$G$1000,MATCH(10,$U$2:$U$999,0)),"")} | C30: {=IFERROR(INDEX('Master Stock'!$J$2:$J$1000,MATCH(10,$U$2:$U$999,0)),"")} | D30: =IF(C30="","",MAX(0,TODAY()-C30)) | E30: {=IFERROR(INDEX('Master Stock'!$D$2:$D$1000,MATCH(10,$V$2:$V$999,0)),"")} | F30: {=IFERROR(INDEX('Master Stock'!$G$2:$G$1000,MATCH(10,$V$2:$V$999,0)),"")} | G30: {=IFERROR(INDEX('Master Stock'!$L$2:$L$1000,MATCH(10,$V$2:$V$999,0)),"")} | H30: =IF(G30="","",MAX(0,TODAY()-G30)) | U30: =IF(AND('Master Stock'!D30<>"",'Master Stock'!H30="OCCUPIED",ISNUMBER('Master Stock'!J30),'Master Stock'!K30=""),SUMPRODUCT(--('Master Stock'!$D$2:$D$1000<>""),--('Master Stock'!$H$2:$H$1000="OCCUPIED"),--ISNUMBER('Master Stock'!$J$2:$J$1000),--('Master Stock'!$K$2:$K$1000=""),--('Master Stock'!$J$2:$J$1000<'Master Stock'!J30))+COUNTIFS('Master Stock'!$J$2:J30,'Master Stock'!J30,'Master Stock'!$D$2:D30,"<>",'Master Stock'!$H$2:H30,"OCCUPIED",'Master Stock'!$K$2:K30,""),"") | V30: =IF(AND('Master Stock'!D30<>"",'Master Stock'!H30="OCCUPIED",ISNUMBER('Master Stock'!L30),'Master Stock'!L30<TODAY()-30),SUMPRODUCT(--('Master Stock'!$D$2:$D$1000<>""),--('Master Stock'!$H$2:$H$1000="OCCUPIED"),--ISNUMBER('Master Stock'!$L$2:$L$1000),--('Master Stock'!$L$2:$L$1000<TODAY()-30),--('Master Stock'!$L$2:$L$1000<'Master Stock'!L30))+COUNTIFS('Master Stock'!$L$2:L30,'Master Stock'!L30,'Master Stock'!$D$2:D30,"<>",'Master Stock'!$H$2:H30,"OCCUPIED"),"")
A31: {=IFERROR(INDEX('Master Stock'!$D$2:$D$1000,MATCH(11,$U$2:$U$999,0)),"")} | B31: {=IFERROR(INDEX('Master Stock'!$G$2:$G$1000,MATCH(11,$U$2:$U$999,0)),"")} | C31: {=IFERROR(INDEX('Master Stock'!$J$2:$J$1000,MATCH(11,$U$2:$U$999,0)),"")} | D31: =IF(C31="","",MAX(0,TODAY()-C31)) | E31: {=IFERROR(INDEX('Master Stock'!$D$2:$D$1000,MATCH(11,$V$2:$V$999,0)),"")} | F31: {=IFERROR(INDEX('Master Stock'!$G$2:$G$1000,MATCH(11,$V$2:$V$999,0)),"")} | G31: {=IFERROR(INDEX('Master Stock'!$L$2:$L$1000,MATCH(11,$V$2:$V$999,0)),"")} | H31: =IF(G31="","",MAX(0,TODAY()-G31)) | U31: =IF(AND('Master Stock'!D31<>"",'Master Stock'!H31="OCCUPIED",ISNUMBER('Master Stock'!J31),'Master Stock'!K31=""),SUMPRODUCT(--('Master Stock'!$D$2:$D$1000<>""),--('Master Stock'!$H$2:$H$1000="OCCUPIED"),--ISNUMBER('Master Stock'!$J$2:$J$1000),--('Master Stock'!$K$2:$K$1000=""),--('Master Stock'!$J$2:$J$1000<'Master Stock'!J31))+COUNTIFS('Master Stock'!$J$2:J31,'Master Stock'!J31,'Master Stock'!$D$2:D31,"<>",'Master Stock'!$H$2:H31,"OCCUPIED",'Master Stock'!$K$2:K31,""),"") | V31: =IF(AND('Master Stock'!D31<>"",'Master Stock'!H31="OCCUPIED",ISNUMBER('Master Stock'!L31),'Master Stock'!L31<TODAY()-30),SUMPRODUCT(--('Master Stock'!$D$2:$D$1000<>""),--('Master Stock'!$H$2:$H$1000="OCCUPIED"),--ISNUMBER('Master Stock'!$L$2:$L$1000),--('Master Stock'!$L$2:$L$1000<TODAY()-30),--('Master Stock'!$L$2:$L$1000<'Master Stock'!L31))+COUNTIFS('Master Stock'!$L$2:L31,'Master Stock'!L31,'Master Stock'!$D$2:D31,"<>",'Master Stock'!$H$2:H31,"OCCUPIED"),"")
A32: {=IFERROR(INDEX('Master Stock'!$D$2:$D$1000,MATCH(12,$U$2:$U$999,0)),"")} | B32: {=IFERROR(INDEX('Master Stock'!$G$2:$G$1000,MATCH(12,$U$2:$U$999,0)),"")} | C32: {=IFERROR(INDEX('Master Stock'!$J$2:$J$1000,MATCH(12,$U$2:$U$999,0)),"")} | D32: =IF(C32="","",MAX(0,TODAY()-C32)) | E32: {=IFERROR(INDEX('Master Stock'!$D$2:$D$1000,MATCH(12,$V$2:$V$999,0)),"")} | F32: {=IFERROR(INDEX('Master Stock'!$G$2:$G$1000,MATCH(12,$V$2:$V$999,0)),"")} | G32: {=IFERROR(INDEX('Master Stock'!$L$2:$L$1000,MATCH(12,$V$2:$V$999,0)),"")} | H32: =IF(G32="","",MAX(0,TODAY()-G32)) | U32: =IF(AND('Master Stock'!D32<>"",'Master Stock'!H32="OCCUPIED",ISNUMBER('Master Stock'!J32),'Master Stock'!K32=""),SUMPRODUCT(--('Master Stock'!$D$2:$D$1000<>""),--('Master Stock'!$H$2:$H$1000="OCCUPIED"),--ISNUMBER('Master Stock'!$J$2:$J$1000),--('Master Stock'!$K$2:$K$1000=""),--('Master Stock'!$J$2:$J$1000<'Master Stock'!J32))+COUNTIFS('Master Stock'!$J$2:J32,'Master Stock'!J32,'Master Stock'!$D$2:D32,"<>",'Master Stock'!$H$2:H32,"OCCUPIED",'Master Stock'!$K$2:K32,""),"") | V32: =IF(AND('Master Stock'!D32<>"",'Master Stock'!H32="OCCUPIED",ISNUMBER('Master Stock'!L32),'Master Stock'!L32<TODAY()-30),SUMPRODUCT(--('Master Stock'!$D$2:$D$1000<>""),--('Master Stock'!$H$2:$H$1000="OCCUPIED"),--ISNUMBER('Master Stock'!$L$2:$L$1000),--('Master Stock'!$L$2:$L$1000<TODAY()-30),--('Master Stock'!$L$2:$L$1000<'Master Stock'!L32))+COUNTIFS('Master Stock'!$L$2:L32,'Master Stock'!L32,'Master Stock'!$D$2:D32,"<>",'Master Stock'!$H$2:H32,"OCCUPIED"),"")
A33: {=IFERROR(INDEX('Master Stock'!$D$2:$D$1000,MATCH(13,$U$2:$U$999,0)),"")} | B33: {=IFERROR(INDEX('Master Stock'!$G$2:$G$1000,MATCH(13,$U$2:$U$999,0)),"")} | C33: {=IFERROR(INDEX('Master Stock'!$J$2:$J$1000,MATCH(13,$U$2:$U$999,0)),"")} | D33: =IF(C33="","",MAX(0,TODAY()-C33)) | E33: {=IFERROR(INDEX('Master Stock'!$D$2:$D$1000,MATCH(13,$V$2:$V$999,0)),"")} | F33: {=IFERROR(INDEX('Master Stock'!$G$2:$G$1000,MATCH(13,$V$2:$V$999,0)),"")} | G33: {=IFERROR(INDEX('Master Stock'!$L$2:$L$1000,MATCH(13,$V$2:$V$999,0)),"")} | H33: =IF(G33="","",MAX(0,TODAY()-G33)) | U33: =IF(AND('Master Stock'!D33<>"",'Master Stock'!H33="OCCUPIED",ISNUMBER('Master Stock'!J33),'Master Stock'!K33=""),SUMPRODUCT(--('Master Stock'!$D$2:$D$1000<>""),--('Master Stock'!$H$2:$H$1000="OCCUPIED"),--ISNUMBER('Master Stock'!$J$2:$J$1000),--('Master Stock'!$K$2:$K$1000=""),--('Master Stock'!$J$2:$J$1000<'Master Stock'!J33))+COUNTIFS('Master Stock'!$J$2:J33,'Master Stock'!J33,'Master Stock'!$D$2:D33,"<>",'Master Stock'!$H$2:H33,"OCCUPIED",'Master Stock'!$K$2:K33,""),"") | V33: =IF(AND('Master Stock'!D33<>"",'Master Stock'!H33="OCCUPIED",ISNUMBER('Master Stock'!L33),'Master Stock'!L33<TODAY()-30),SUMPRODUCT(--('Master Stock'!$D$2:$D$1000<>""),--('Master Stock'!$H$2:$H$1000="OCCUPIED"),--ISNUMBER('Master Stock'!$L$2:$L$1000),--('Master Stock'!$L$2:$L$1000<TODAY()-30),--('Master Stock'!$L$2:$L$1000<'Master Stock'!L33))+COUNTIFS('Master Stock'!$L$2:L33,'Master Stock'!L33,'Master Stock'!$D$2:D33,"<>",'Master Stock'!$H$2:H33,"OCCUPIED"),"")
A34: {=IFERROR(INDEX('Master Stock'!$D$2:$D$1000,MATCH(14,$U$2:$U$999,0)),"")} | B34: {=IFERROR(INDEX('Master Stock'!$G$2:$G$1000,MATCH(14,$U$2:$U$999,0)),"")} | C34: {=IFERROR(INDEX('Master Stock'!$J$2:$J$1000,MATCH(14,$U$2:$U$999,0)),"")} | D34: =IF(C34="","",MAX(0,TODAY()-C34)) | E34: {=IFERROR(INDEX('Master Stock'!$D$2:$D$1000,MATCH(14,$V$2:$V$999,0)),"")} | F34: {=IFERROR(INDEX('Master Stock'!$G$2:$G$1000,MATCH(14,$V$2:$V$999,0)),"")} | G34: {=IFERROR(INDEX('Master Stock'!$L$2:$L$1000,MATCH(14,$V$2:$V$999,0)),"")} | H34: =IF(G34="","",MAX(0,TODAY()-G34)) | U34: =IF(AND('Master Stock'!D34<>"",'Master Stock'!H34="OCCUPIED",ISNUMBER('Master Stock'!J34),'Master Stock'!K34=""),SUMPRODUCT(--('Master Stock'!$D$2:$D$1000<>""),--('Master Stock'!$H$2:$H$1000="OCCUPIED"),--ISNUMBER('Master Stock'!$J$2:$J$1000),--('Master Stock'!$K$2:$K$1000=""),--('Master Stock'!$J$2:$J$1000<'Master Stock'!J34))+COUNTIFS('Master Stock'!$J$2:J34,'Master Stock'!J34,'Master Stock'!$D$2:D34,"<>",'Master Stock'!$H$2:H34,"OCCUPIED",'Master Stock'!$K$2:K34,""),"") | V34: =IF(AND('Master Stock'!D34<>"",'Master Stock'!H34="OCCUPIED",ISNUMBER('Master Stock'!L34),'Master Stock'!L34<TODAY()-30),SUMPRODUCT(--('Master Stock'!$D$2:$D$1000<>""),--('Master Stock'!$H$2:$H$1000="OCCUPIED"),--ISNUMBER('Master Stock'!$L$2:$L$1000),--('Master Stock'!$L$2:$L$1000<TODAY()-30),--('Master Stock'!$L$2:$L$1000<'Master Stock'!L34))+COUNTIFS('Master Stock'!$L$2:L34,'Master Stock'!L34,'Master Stock'!$D$2:D34,"<>",'Master Stock'!$H$2:H34,"OCCUPIED"),"")
A35: {=IFERROR(INDEX('Master Stock'!$D$2:$D$1000,MATCH(15,$U$2:$U$999,0)),"")} | B35: {=IFERROR(INDEX('Master Stock'!$G$2:$G$1000,MATCH(15,$U$2:$U$999,0)),"")} | C35: {=IFERROR(INDEX('Master Stock'!$J$2:$J$1000,MATCH(15,$U$2:$U$999,0)),"")} | D35: =IF(C35="","",MAX(0,TODAY()-C35)) | E35: {=IFERROR(INDEX('Master Stock'!$D$2:$D$1000,MATCH(15,$V$2:$V$999,0)),"")} | F35: {=IFERROR(INDEX('Master Stock'!$G$2:$G$1000,MATCH(15,$V$2:$V$999,0)),"")} | G35: {=IFERROR(INDEX('Master Stock'!$L$2:$L$1000,MATCH(15,$V$2:$V$999,0)),"")} | H35: =IF(G35="","",MAX(0,TODAY()-G35)) | U35: =IF(AND('Master Stock'!D35<>"",'Master Stock'!H35="OCCUPIED",ISNUMBER('Master Stock'!J35),'Master Stock'!K35=""),SUMPRODUCT(--('Master Stock'!$D$2:$D$1000<>""),--('Master Stock'!$H$2:$H$1000="OCCUPIED"),--ISNUMBER('Master Stock'!$J$2:$J$1000),--('Master Stock'!$K$2:$K$1000=""),--('Master Stock'!$J$2:$J$1000<'Master Stock'!J35))+COUNTIFS('Master Stock'!$J$2:J35,'Master Stock'!J35,'Master Stock'!$D$2:D35,"<>",'Master Stock'!$H$2:H35,"OCCUPIED",'Master Stock'!$K$2:K35,""),"") | V35: =IF(AND('Master Stock'!D35<>"",'Master Stock'!H35="OCCUPIED",ISNUMBER('Master Stock'!L35),'Master Stock'!L35<TODAY()-30),SUMPRODUCT(--('Master Stock'!$D$2:$D$1000<>""),--('Master Stock'!$H$2:$H$1000="OCCUPIED"),--ISNUMBER('Master Stock'!$L$2:$L$1000),--('Master Stock'!$L$2:$L$1000<TODAY()-30),--('Master Stock'!$L$2:$L$1000<'Master Stock'!L35))+COUNTIFS('Master Stock'!$L$2:L35,'Master Stock'!L35,'Master Stock'!$D$2:D35,"<>",'Master Stock'!$H$2:H35,"OCCUPIED"),"")
A36: {=IFERROR(INDEX('Master Stock'!$D$2:$D$1000,MATCH(16,$U$2:$U$999,0)),"")} | B36: {=IFERROR(INDEX('Master Stock'!$G$2:$G$1000,MATCH(16,$U$2:$U$999,0)),"")} | C36: {=IFERROR(INDEX('Master Stock'!$J$2:$J$1000,MATCH(16,$U$2:$U$999,0)),"")} | D36: =IF(C36="","",MAX(0,TODAY()-C36)) | E36: {=IFERROR(INDEX('Master Stock'!$D$2:$D$1000,MATCH(16,$V$2:$V$999,0)),"")} | F36: {=IFERROR(INDEX('Master Stock'!$G$2:$G$1000,MATCH(16,$V$2:$V$999,0)),"")} | G36: {=IFERROR(INDEX('Master Stock'!$L$2:$L$1000,MATCH(16,$V$2:$V$999,0)),"")} | H36: =IF(G36="","",MAX(0,TODAY()-G36)) | U36: =IF(AND('Master Stock'!D36<>"",'Master Stock'!H36="OCCUPIED",ISNUMBER('Master Stock'!J36),'Master Stock'!K36=""),SUMPRODUCT(--('Master Stock'!$D$2:$D$1000<>""),--('Master Stock'!$H$2:$H$1000="OCCUPIED"),--ISNUMBER('Master Stock'!$J$2:$J$1000),--('Master Stock'!$K$2:$K$1000=""),--('Master Stock'!$J$2:$J$1000<'Master Stock'!J36))+COUNTIFS('Master Stock'!$J$2:J36,'Master Stock'!J36,'Master Stock'!$D$2:D36,"<>",'Master Stock'!$H$2:H36,"OCCUPIED",'Master Stock'!$K$2:K36,""),"") | V36: =IF(AND('Master Stock'!D36<>"",'Master Stock'!H36="OCCUPIED",ISNUMBER('Master Stock'!L36),'Master Stock'!L36<TODAY()-30),SUMPRODUCT(--('Master Stock'!$D$2:$D$1000<>""),--('Master Stock'!$H$2:$H$1000="OCCUPIED"),--ISNUMBER('Master Stock'!$L$2:$L$1000),--('Master Stock'!$L$2:$L$1000<TODAY()-30),--('Master Stock'!$L$2:$L$1000<'Master Stock'!L36))+COUNTIFS('Master Stock'!$L$2:L36,'Master Stock'!L36,'Master Stock'!$D$2:D36,"<>",'Master Stock'!$H$2:H36,"OCCUPIED"),"")
A37: {=IFERROR(INDEX('Master Stock'!$D$2:$D$1000,MATCH(17,$U$2:$U$999,0)),"")} | B37: {=IFERROR(INDEX('Master Stock'!$G$2:$G$1000,MATCH(17,$U$2:$U$999,0)),"")} | C37: {=IFERROR(INDEX('Master Stock'!$J$2:$J$1000,MATCH(17,$U$2:$U$999,0)),"")} | D37: =IF(C37="","",MAX(0,TODAY()-C37)) | E37: {=IFERROR(INDEX('Master Stock'!$D$2:$D$1000,MATCH(17,$V$2:$V$999,0)),"")} | F37: {=IFERROR(INDEX('Master Stock'!$G$2:$G$1000,MATCH(17,$V$2:$V$999,0)),"")} | G37: {=IFERROR(INDEX('Master Stock'!$L$2:$L$1000,MATCH(17,$V$2:$V$999,0)),"")} | H37: =IF(G37="","",MAX(0,TODAY()-G37)) | U37: =IF(AND('Master Stock'!D37<>"",'Master Stock'!H37="OCCUPIED",ISNUMBER('Master Stock'!J37),'Master Stock'!K37=""),SUMPRODUCT(--('Master Stock'!$D$2:$D$1000<>""),--('Master Stock'!$H$2:$H$1000="OCCUPIED"),--ISNUMBER('Master Stock'!$J$2:$J$1000),--('Master Stock'!$K$2:$K$1000=""),--('Master Stock'!$J$2:$J$1000<'Master Stock'!J37))+COUNTIFS('Master Stock'!$J$2:J37,'Master Stock'!J37,'Master Stock'!$D$2:D37,"<>",'Master Stock'!$H$2:H37,"OCCUPIED",'Master Stock'!$K$2:K37,""),"") | V37: =IF(AND('Master Stock'!D37<>"",'Master Stock'!H37="OCCUPIED",ISNUMBER('Master Stock'!L37),'Master Stock'!L37<TODAY()-30),SUMPRODUCT(--('Master Stock'!$D$2:$D$1000<>""),--('Master Stock'!$H$2:$H$1000="OCCUPIED"),--ISNUMBER('Master Stock'!$L$2:$L$1000),--('Master Stock'!$L$2:$L$1000<TODAY()-30),--('Master Stock'!$L$2:$L$1000<'Master Stock'!L37))+COUNTIFS('Master Stock'!$L$2:L37,'Master Stock'!L37,'Master Stock'!$D$2:D37,"<>",'Master Stock'!$H$2:H37,"OCCUPIED"),"")
A38: {=IFERROR(INDEX('Master Stock'!$D$2:$D$1000,MATCH(18,$U$2:$U$999,0)),"")} | B38: {=IFERROR(INDEX('Master Stock'!$G$2:$G$1000,MATCH(18,$U$2:$U$999,0)),"")} | C38: {=IFERROR(INDEX('Master Stock'!$J$2:$J$1000,MATCH(18,$U$2:$U$999,0)),"")} | D38: =IF(C38="","",MAX(0,TODAY()-C38)) | E38: {=IFERROR(INDEX('Master Stock'!$D$2:$D$1000,MATCH(18,$V$2:$V$999,0)),"")} | F38: {=IFERROR(INDEX('Master Stock'!$G$2:$G$1000,MATCH(18,$V$2:$V$999,0)),"")} | G38: {=IFERROR(INDEX('Master Stock'!$L$2:$L$1000,MATCH(18,$V$2:$V$999,0)),"")} | H38: =IF(G38="","",MAX(0,TODAY()-G38)) | U38: =IF(AND('Master Stock'!D38<>"",'Master Stock'!H38="OCCUPIED",ISNUMBER('Master Stock'!J38),'Master Stock'!K38=""),SUMPRODUCT(--('Master Stock'!$D$2:$D$1000<>""),--('Master Stock'!$H$2:$H$1000="OCCUPIED"),--ISNUMBER('Master Stock'!$J$2:$J$1000),--('Master Stock'!$K$2:$K$1000=""),--('Master Stock'!$J$2:$J$1000<'Master Stock'!J38))+COUNTIFS('Master Stock'!$J$2:J38,'Master Stock'!J38,'Master Stock'!$D$2:D38,"<>",'Master Stock'!$H$2:H38,"OCCUPIED",'Master Stock'!$K$2:K38,""),"") | V38: =IF(AND('Master Stock'!D38<>"",'Master Stock'!H38="OCCUPIED",ISNUMBER('Master Stock'!L38),'Master Stock'!L38<TODAY()-30),SUMPRODUCT(--('Master Stock'!$D$2:$D$1000<>""),--('Master Stock'!$H$2:$H$1000="OCCUPIED"),--ISNUMBER('Master Stock'!$L$2:$L$1000),--('Master Stock'!$L$2:$L$1000<TODAY()-30),--('Master Stock'!$L$2:$L$1000<'Master Stock'!L38))+COUNTIFS('Master Stock'!$L$2:L38,'Master Stock'!L38,'Master Stock'!$D$2:D38,"<>",'Master Stock'!$H$2:H38,"OCCUPIED"),"")
A39: {=IFERROR(INDEX('Master Stock'!$D$2:$D$1000,MATCH(19,$U$2:$U$999,0)),"")} | B39: {=IFERROR(INDEX('Master Stock'!$G$2:$G$1000,MATCH(19,$U$2:$U$999,0)),"")} | C39: {=IFERROR(INDEX('Master Stock'!$J$2:$J$1000,MATCH(19,$U$2:$U$999,0)),"")} | D39: =IF(C39="","",MAX(0,TODAY()-C39)) | E39: {=IFERROR(INDEX('Master Stock'!$D$2:$D$1000,MATCH(19,$V$2:$V$999,0)),"")} | F39: {=IFERROR(INDEX('Master Stock'!$G$2:$G$1000,MATCH(19,$V$2:$V$999,0)),"")} | G39: {=IFERROR(INDEX('Master Stock'!$L$2:$L$1000,MATCH(19,$V$2:$V$999,0)),"")} | H39: =IF(G39="","",MAX(0,TODAY()-G39)) | U39: =IF(AND('Master Stock'!D39<>"",'Master Stock'!H39="OCCUPIED",ISNUMBER('Master Stock'!J39),'Master Stock'!K39=""),SUMPRODUCT(--('Master Stock'!$D$2:$D$1000<>""),--('Master Stock'!$H$2:$H$1000="OCCUPIED"),--ISNUMBER('Master Stock'!$J$2:$J$1000),--('Master Stock'!$K$2:$K$1000=""),--('Master Stock'!$J$2:$J$1000<'Master Stock'!J39))+COUNTIFS('Master Stock'!$J$2:J39,'Master Stock'!J39,'Master Stock'!$D$2:D39,"<>",'Master Stock'!$H$2:H39,"OCCUPIED",'Master Stock'!$K$2:K39,""),"") | V39: =IF(AND('Master Stock'!D39<>"",'Master Stock'!H39="OCCUPIED",ISNUMBER('Master Stock'!L39),'Master Stock'!L39<TODAY()-30),SUMPRODUCT(--('Master Stock'!$D$2:$D$1000<>""),--('Master Stock'!$H$2:$H$1000="OCCUPIED"),--ISNUMBER('Master Stock'!$L$2:$L$1000),--('Master Stock'!$L$2:$L$1000<TODAY()-30),--('Master Stock'!$L$2:$L$1000<'Master Stock'!L39))+COUNTIFS('Master Stock'!$L$2:L39,'Master Stock'!L39,'Master Stock'!$D$2:D39,"<>",'Master Stock'!$H$2:H39,"OCCUPIED"),"")
A40: {=IFERROR(INDEX('Master Stock'!$D$2:$D$1000,MATCH(20,$U$2:$U$999,0)),"")} | B40: {=IFERROR(INDEX('Master Stock'!$G$2:$G$1000,MATCH(20,$U$2:$U$999,0)),"")} | C40: {=IFERROR(INDEX('Master Stock'!$J$2:$J$1000,MATCH(20,$U$2:$U$999,0)),"")} | D40: =IF(C40="","",MAX(0,TODAY()-C40)) | E40: {=IFERROR(INDEX('Master Stock'!$D$2:$D$1000,MATCH(20,$V$2:$V$999,0)),"")} | F40: {=IFERROR(INDEX('Master Stock'!$G$2:$G$1000,MATCH(20,$V$2:$V$999,0)),"")} | G40: {=IFERROR(INDEX('Master Stock'!$L$2:$L$1000,MATCH(20,$V$2:$V$999,0)),"")} | H40: =IF(G40="","",MAX(0,TODAY()-G40)) | U40: =IF(AND('Master Stock'!D40<>"",'Master Stock'!H40="OCCUPIED",ISNUMBER('Master Stock'!J40),'Master Stock'!K40=""),SUMPRODUCT(--('Master Stock'!$D$2:$D$1000<>""),--('Master Stock'!$H$2:$H$1000="OCCUPIED"),--ISNUMBER('Master Stock'!$J$2:$J$1000),--('Master Stock'!$K$2:$K$1000=""),--('Master Stock'!$J$2:$J$1000<'Master Stock'!J40))+COUNTIFS('Master Stock'!$J$2:J40,'Master Stock'!J40,'Master Stock'!$D$2:D40,"<>",'Master Stock'!$H$2:H40,"OCCUPIED",'Master Stock'!$K$2:K40,""),"") | V40: =IF(AND('Master Stock'!D40<>"",'Master Stock'!H40="OCCUPIED",ISNUMBER('Master Stock'!L40),'Master Stock'!L40<TODAY()-30),SUMPRODUCT(--('Master Stock'!$D$2:$D$1000<>""),--('Master Stock'!$H$2:$H$1000="OCCUPIED"),--ISNUMBER('Master Stock'!$L$2:$L$1000),--('Master Stock'!$L$2:$L$1000<TODAY()-30),--('Master Stock'!$L$2:$L$1000<'Master Stock'!L40))+COUNTIFS('Master Stock'!$L$2:L40,'Master Stock'!L40,'Master Stock'!$D$2:D40,"<>",'Master Stock'!$H$2:H40,"OCCUPIED"),"")
...

Sheet Dashboard
A1: GODOWN STOCK & TREATMENT DASHBOARD
A3: TOTAL STACKS | C3: OCCUPIED STACKS | E3: CURRENTLY UNDER COVER | G3: TOTAL DEGASSING DUE | I3: TOTAL EMPTY STACKS
A4: =COUNTA('Master Stock'!$C$2:$C$99) | C4: =COUNTIF('Master Stock'!$H$2:$H$99,"OCCUPIED") | E4: =COUNTIFS('Master Stock'!$H$2:$H$99,"OCCUPIED",'Master Stock'!$J$2:$J$99,"<>",'Master Stock'!$K$2:$K$99,"") | G4: =SUM('Master Stock'!$O$2:$O$99) | L4: ='Shed Summary'!D7
A7: CURRENTLY UNDER COVER – STACK DETAILS | G7: FUMIGATION MORE THAN 5 DAYS – DEGASSING DUE
A8: Shed | B8: Stack No. | C8: Fumigation Date | D8: Days Count | G8: Shed | H8: Stack No. | I8: Fumigation Date | J8: Days Count
A9: =IFERROR(__xludf.DUMMYFUNCTION("IFERROR(FILTER('Master Stock'!$C$2:$C$99,('Master Stock'!$H$2:$H$99=""OCCUPIED"")*ISNUMBER('Master Stock'!$J$2:$J$99)*('Master Stock'!$K$2:$K$99="""")),"""")"),9.0) | B9: =IFERROR(__xludf.DUMMYFUNCTION("IFERROR(FILTER('Master Stock'!$D$2:$D$99,('Master Stock'!$H$2:$H$99=""OCCUPIED"")*ISNUMBER('Master Stock'!$J$2:$J$99)*('Master Stock'!$K$2:$K$99="""")),"""")"),"9A03") | C9: =IFERROR(__xludf.DUMMYFUNCTION("IFERROR(FILTER('Master Stock'!$J$2:$J$99,('Master Stock'!$H$2:$H$99=""OCCUPIED"")*ISNUMBER('Master Stock'!$J$2:$J$99)*('Master Stock'!$K$2:$K$99="""")),"""")"),46265.0) | D9: =IF(C9="","",MAX(0,TODAY()-C9)) | G9: =IFERROR(__xludf.DUMMYFUNCTION("IFERROR(FILTER('Master Stock'!$C$2:$C$99,('Master Stock'!$H$2:$H$99=""OCCUPIED"")*ISNUMBER('Master Stock'!$L$2:$L$99)*('Master Stock'!$L$2:$L$99<TODAY()-30)),"""")"),9.0) | H9: =IFERROR(__xludf.DUMMYFUNCTION("IFERROR(FILTER('Master Stock'!$D$2:$D$99,('Master Stock'!$H$2:$H$99=""OCCUPIED"")*ISNUMBER('Master Stock'!$L$2:$L$99)*('Master Stock'!$L$2:$L$99<TODAY()-30)),"""")"),"9A01") | I9: =IFERROR(__xludf.DUMMYFUNCTION("IFERROR(FILTER('Master Stock'!$L$2:$L$99,('Master Stock'!$H$2:$H$99=""OCCUPIED"")*ISNUMBER('Master Stock'!$L$2:$L$99)*('Master Stock'!$L$2:$L$99<TODAY()-30)),"""")"),46162.0) | J9: =IF(I9="","",MAX(0,TODAY()-I9))
A10: =IFERROR(__xludf.DUMMYFUNCTION("""COMPUTED_VALUE"""),14.0) | B10: =IFERROR(__xludf.DUMMYFUNCTION("""COMPUTED_VALUE"""),"14A02") | C10: =IFERROR(__xludf.DUMMYFUNCTION("""COMPUTED_VALUE"""),46265.0) | D10: =IF(C10="","",MAX(0,TODAY()-C10)) | G10: =IFERROR(__xludf.DUMMYFUNCTION("""COMPUTED_VALUE"""),9.0) | H10: =IFERROR(__xludf.DUMMYFUNCTION("""COMPUTED_VALUE"""),"9A02") | I10: =IFERROR(__xludf.DUMMYFUNCTION("""COMPUTED_VALUE"""),46228.0) | J10: =IF(I10="","",MAX(0,TODAY()-I10))
A11: =IFERROR(__xludf.DUMMYFUNCTION("""COMPUTED_VALUE"""),14.0) | B11: =IFERROR(__xludf.DUMMYFUNCTION("""COMPUTED_VALUE"""),"14B14") | C11: =IFERROR(__xludf.DUMMYFUNCTION("""COMPUTED_VALUE"""),46265.0) | D11: =IF(C11="","",MAX(0,TODAY()-C11)) | G11: =IFERROR(__xludf.DUMMYFUNCTION("""COMPUTED_VALUE"""),9.0) | H11: =IFERROR(__xludf.DUMMYFUNCTION("""COMPUTED_VALUE"""),"9A04") | I11: =IFERROR(__xludf.DUMMYFUNCTION("""COMPUTED_VALUE"""),46235.0) | J11: =IF(I11="","",MAX(0,TODAY()-I11))
A12: =IFERROR(__xludf.DUMMYFUNCTION("""COMPUTED_VALUE"""),14.0) | B12: =IFERROR(__xludf.DUMMYFUNCTION("""COMPUTED_VALUE"""),"14B15") | C12: =IFERROR(__xludf.DUMMYFUNCTION("""COMPUTED_VALUE"""),46265.0) | D12: =IF(C12="","",MAX(0,TODAY()-C12)) | G12: =IFERROR(__xludf.DUMMYFUNCTION("""COMPUTED_VALUE"""),9.0) | H12: =IFERROR(__xludf.DUMMYFUNCTION("""COMPUTED_VALUE"""),"9A05") | I12: =IFERROR(__xludf.DUMMYFUNCTION("""COMPUTED_VALUE"""),46156.0) | J12: =IF(I12="","",MAX(0,TODAY()-I12))
A13: =IFERROR(__xludf.DUMMYFUNCTION("""COMPUTED_VALUE"""),18.0) | B13: =IFERROR(__xludf.DUMMYFUNCTION("""COMPUTED_VALUE"""),"18A02") | C13: =IFERROR(__xludf.DUMMYFUNCTION("""COMPUTED_VALUE"""),46265.0) | D13: =IF(C13="","",MAX(0,TODAY()-C13)) | G13: =IFERROR(__xludf.DUMMYFUNCTION("""COMPUTED_VALUE"""),9.0) | H13: =IFERROR(__xludf.DUMMYFUNCTION("""COMPUTED_VALUE"""),"9A07") | I13: =IFERROR(__xludf.DUMMYFUNCTION("""COMPUTED_VALUE"""),46228.0) | J13: =IF(I13="","",MAX(0,TODAY()-I13))
D14: =IF(C14="","",MAX(0,TODAY()-C14)) | G14: =IFERROR(__xludf.DUMMYFUNCTION("""COMPUTED_VALUE"""),9.0) | H14: =IFERROR(__xludf.DUMMYFUNCTION("""COMPUTED_VALUE"""),"9A08") | I14: =IFERROR(__xludf.DUMMYFUNCTION("""COMPUTED_VALUE"""),46232.0) | J14: =IF(I14="","",MAX(0,TODAY()-I14))
D15: =IF(C15="","",MAX(0,TODAY()-C15)) | G15: =IFERROR(__xludf.DUMMYFUNCTION("""COMPUTED_VALUE"""),9.0) | H15: =IFERROR(__xludf.DUMMYFUNCTION("""COMPUTED_VALUE"""),"9B12") | I15: =IFERROR(__xludf.DUMMYFUNCTION("""COMPUTED_VALUE"""),46235.0) | J15: =IF(I15="","",MAX(0,TODAY()-I15))
D16: =IF(C16="","",MAX(0,TODAY()-C16)) | G16: =IFERROR(__xludf.DUMMYFUNCTION("""COMPUTED_VALUE"""),9.0) | H16: =IFERROR(__xludf.DUMMYFUNCTION("""COMPUTED_VALUE"""),"9B13") | I16: =IFERROR(__xludf.DUMMYFUNCTION("""COMPUTED_VALUE"""),46204.0) | J16: =IF(I16="","",MAX(0,TODAY()-I16))
D17: =IF(C17="","",MAX(0,TODAY()-C17)) | G17: =IFERROR(__xludf.DUMMYFUNCTION("""COMPUTED_VALUE"""),9.0) | H17: =IFERROR(__xludf.DUMMYFUNCTION("""COMPUTED_VALUE"""),"9B15") | I17: =IFERROR(__xludf.DUMMYFUNCTION("""COMPUTED_VALUE"""),46235.0) | J17: =IF(I17="","",MAX(0,TODAY()-I17))
D18: =IF(C18="","",MAX(0,TODAY()-C18)) | G18: =IFERROR(__xludf.DUMMYFUNCTION("""COMPUTED_VALUE"""),9.0) | H18: =IFERROR(__xludf.DUMMYFUNCTION("""COMPUTED_VALUE"""),"9B18") | I18: =IFERROR(__xludf.DUMMYFUNCTION("""COMPUTED_VALUE"""),46235.0) | J18: =IF(I18="","",MAX(0,TODAY()-I18))
D19: =IF(C19="","",MAX(0,TODAY()-C19)) | G19: =IFERROR(__xludf.DUMMYFUNCTION("""COMPUTED_VALUE"""),14.0) | H19: =IFERROR(__xludf.DUMMYFUNCTION("""COMPUTED_VALUE"""),"14A07") | I19: =IFERROR(__xludf.DUMMYFUNCTION("""COMPUTED_VALUE"""),46190.0) | J19: =IF(I19="","",MAX(0,TODAY()-I19))
D20: =IF(C20="","",MAX(0,TODAY()-C20)) | G20: =IFERROR(__xludf.DUMMYFUNCTION("""COMPUTED_VALUE"""),14.0) | H20: =IFERROR(__xludf.DUMMYFUNCTION("""COMPUTED_VALUE"""),"14A08") | I20: =IFERROR(__xludf.DUMMYFUNCTION("""COMPUTED_VALUE"""),46190.0) | J20: =IF(I20="","",MAX(0,TODAY()-I20))
D21: =IF(C21="","",MAX(0,TODAY()-C21)) | G21: =IFERROR(__xludf.DUMMYFUNCTION("""COMPUTED_VALUE"""),14.0) | H21: =IFERROR(__xludf.DUMMYFUNCTION("""COMPUTED_VALUE"""),"14A09") | I21: =IFERROR(__xludf.DUMMYFUNCTION("""COMPUTED_VALUE"""),46190.0) | J21: =IF(I21="","",MAX(0,TODAY()-I21))
D22: =IF(C22="","",MAX(0,TODAY()-C22)) | G22: =IFERROR(__xludf.DUMMYFUNCTION("""COMPUTED_VALUE"""),14.0) | H22: =IFERROR(__xludf.DUMMYFUNCTION("""COMPUTED_VALUE"""),"14B10") | I22: =IFERROR(__xludf.DUMMYFUNCTION("""COMPUTED_VALUE"""),46179.0) | J22: =IF(I22="","",MAX(0,TODAY()-I22))
D23: =IF(C23="","",MAX(0,TODAY()-C23)) | G23: =IFERROR(__xludf.DUMMYFUNCTION("""COMPUTED_VALUE"""),14.0) | H23: =IFERROR(__xludf.DUMMYFUNCTION("""COMPUTED_VALUE"""),"14B11") | I23: =IFERROR(__xludf.DUMMYFUNCTION("""COMPUTED_VALUE"""),46179.0) | J23: =IF(I23="","",MAX(0,TODAY()-I23))
D24: =IF(C24="","",MAX(0,TODAY()-C24)) | G24: =IFERROR(__xludf.DUMMYFUNCTION("""COMPUTED_VALUE"""),14.0) | H24: =IFERROR(__xludf.DUMMYFUNCTION("""COMPUTED_VALUE"""),"14B12") | I24: =IFERROR(__xludf.DUMMYFUNCTION("""COMPUTED_VALUE"""),46179.0) | J24: =IF(I24="","",MAX(0,TODAY()-I24))
D25: =IF(C25="","",MAX(0,TODAY()-C25)) | G25: =IFERROR(__xludf.DUMMYFUNCTION("""COMPUTED_VALUE"""),14.0) | H25: =IFERROR(__xludf.DUMMYFUNCTION("""COMPUTED_VALUE"""),"14B13") | I25: =IFERROR(__xludf.DUMMYFUNCTION("""COMPUTED_VALUE"""),46179.0) | J25: =IF(I25="","",MAX(0,TODAY()-I25))
D26: =IF(C26="","",MAX(0,TODAY()-C26)) | G26: =IFERROR(__xludf.DUMMYFUNCTION("""COMPUTED_VALUE"""),18.0) | H26: =IFERROR(__xludf.DUMMYFUNCTION("""COMPUTED_VALUE"""),"18A01") | I26: =IFERROR(__xludf.DUMMYFUNCTION("""COMPUTED_VALUE"""),46172.0) | J26: =IF(I26="","",MAX(0,TODAY()-I26))
D27: =IF(C27="","",MAX(0,TODAY()-C27)) | G27: =IFERROR(__xludf.DUMMYFUNCTION("""COMPUTED_VALUE"""),18.0) | H27: =IFERROR(__xludf.DUMMYFUNCTION("""COMPUTED_VALUE"""),"18A03") | I27: =IFERROR(__xludf.DUMMYFUNCTION("""COMPUTED_VALUE"""),46202.0) | J27: =IF(I27="","",MAX(0,TODAY()-I27))
D28: =IF(C28="","",MAX(0,TODAY()-C28)) | G28: =IFERROR(__xludf.DUMMYFUNCTION("""COMPUTED_VALUE"""),18.0) | H28: =IFERROR(__xludf.DUMMYFUNCTION("""COMPUTED_VALUE"""),"18A04") | I28: =IFERROR(__xludf.DUMMYFUNCTION("""COMPUTED_VALUE"""),46211.0) | J28: =IF(I28="","",MAX(0,TODAY()-I28))
D29: =IF(C29="","",MAX(0,TODAY()-C29)) | G29: =IFERROR(__xludf.DUMMYFUNCTION("""COMPUTED_VALUE"""),18.0) | H29: =IFERROR(__xludf.DUMMYFUNCTION("""COMPUTED_VALUE"""),"18A07") | I29: =IFERROR(__xludf.DUMMYFUNCTION("""COMPUTED_VALUE"""),46207.0) | J29: =IF(I29="","",MAX(0,TODAY()-I29))
