Workbook

Sheet Dashboard
A1: GODOWN STOCK & TREATMENT DASHBOARD
A3: TOTAL STACKS | C3: OCCUPIED STACKS | E3: CURRENTLY UNDER COVER | G3: DEGASSING DUE >5 DAYS | L3: FUMIGATION DUE >30 DAYS | M3: =COUNTIFS('Master Stock'!$H$2:$H$100,"OCCUPIED",'Master Stock'!$J$2:$J$100,"<>",'Master Stock'!$K$2:$K$100,"",'Master Stock'!$J$2:$J$100,"<"&TODAY()-30)
A4: =COUNTA('Master Stock'!$C$2:$C$100) | C4: =COUNTIF('Master Stock'!$H$2:$H$100,"OCCUPIED") | E4: =COUNTIFS('Master Stock'!$H$2:$H$100,"OCCUPIED",'Master Stock'!$J$2:$J$100,"<>",'Master Stock'!$K$2:$K$100,"") | G4: =COUNTIFS('Master Stock'!$J$2:$J$100,"<>",'Master Stock'!$K$2:$K$100,"",'Master Stock'!$J$2:$J$100,"<"&TODAY()-5)
A7: CURRENTLY UNDER COVER – STACK DETAILS | G7: FUMIGATION MORE THAN 5 DAYS – DEGASSING DUE | L7: FUMIGATION MORE THAN 30 DAYS – FUMIGATION DUE
A8: Shed | B8: Stack No. | C8: Receipt Date | D8: Fumigation Date | E8: Days Since Fumigation | G8: Shed | H8: Stack No. | I8: Fumigation Date | J8: Days Since Fumigation | L8: Shed | M8: Stack No. | N8: Fumigation Date | O8: Days Since Fumigation
A9: =IFERROR(INDEX('Master Stock'!$C$2:$C$100,MATCH(ROWS($A$9:A9),'Master Stock'!$N$2:$N$100,0)),"") | B9: =IFERROR(INDEX('Master Stock'!$D$2:$D$100,MATCH(ROWS($A$9:A9),'Master Stock'!$N$2:$N$100,0)),"") | C9: =IFERROR(INDEX('Master Stock'!$B$2:$B$100,MATCH(ROWS($A$9:A9),'Master Stock'!$N$2:$N$100,0)),"") | D9: =IFERROR(INDEX('Master Stock'!$J$2:$J$100,MATCH(ROWS($A$9:A9),'Master Stock'!$N$2:$N$100,0)),"") | E9: =IF(D9="","",MAX(0,TODAY()-(IF(ISNUMBER(D9),D9,IFERROR(DATE(2000+VALUE(RIGHT(D9,2)),VALUE(MID(D9,4,2)),VALUE(LEFT(D9,2))),""))))) | G9: =IFERROR(INDEX('Master Stock'!$C$2:$C$100,MATCH(ROWS($G$9:G9),'Master Stock'!$P$2:$P$100,0)),"") | H9: =IFERROR(INDEX('Master Stock'!$D$2:$D$100,MATCH(ROWS($G$9:G9),'Master Stock'!$P$2:$P$100,0)),"") | I9: =IFERROR(INDEX('Master Stock'!$J$2:$J$100,MATCH(ROWS($G$9:G9),'Master Stock'!$P$2:$P$100,0)),"") | J9: =IF(I9="","",MAX(0,TODAY()-(IF(ISNUMBER(I9),I9,IFERROR(DATE(2000+VALUE(RIGHT(I9,2)),VALUE(MID(I9,4,2)),VALUE(LEFT(I9,2))),""))))) | L9: =IFERROR(INDEX('Master Stock'!$C$2:$C$100,AGGREGATE(15,6,(ROW('Master Stock'!$C$2:$C$100)-ROW('Master Stock'!$C$2)+1)/(('Master Stock'!$H$2:$H$100="OCCUPIED")*('Master Stock'!$J$2:$J$100<>"")*('Master Stock'!$K$2:$K$100="")*('Master Stock'!$J$2:$J$100<TODAY()-30)),1)),"") | M9: =IFERROR(INDEX('Master Stock'!$D$2:$D$100,AGGREGATE(15,6,(ROW('Master Stock'!$C$2:$C$100)-ROW('Master Stock'!$C$2)+1)/(('Master Stock'!$H$2:$H$100="OCCUPIED")*('Master Stock'!$J$2:$J$100<>"")*('Master Stock'!$K$2:$K$100="")*('Master Stock'!$J$2:$J$100<TODAY()-30)),1)),"") | N9: =IFERROR(INDEX('Master Stock'!$J$2:$J$100,AGGREGATE(15,6,(ROW('Master Stock'!$C$2:$C$100)-ROW('Master Stock'!$C$2)+1)/(('Master Stock'!$H$2:$H$100="OCCUPIED")*('Master Stock'!$J$2:$J$100<>"")*('Master Stock'!$K$2:$K$100="")*('Master Stock'!$J$2:$J$100<TODAY()-30)),1)),"") | O9: =IF(N9="","",MAX(0,TODAY()-(IF(ISNUMBER(N9),N9,IFERROR(DATE(2000+VALUE(RIGHT(N9,2)),VALUE(MID(N9,4,2)),VALUE(LEFT(N9,2))),"")))))
A10: =IFERROR(INDEX('Master Stock'!$C$2:$C$100,MATCH(ROWS($A$9:A10),'Master Stock'!$N$2:$N$100,0)),"") | B10: =IFERROR(INDEX('Master Stock'!$D$2:$D$100,MATCH(ROWS($A$9:A10),'Master Stock'!$N$2:$N$100,0)),"") | C10: =IFERROR(INDEX('Master Stock'!$B$2:$B$100,MATCH(ROWS($A$9:A10),'Master Stock'!$N$2:$N$100,0)),"") | D10: =IFERROR(INDEX('Master Stock'!$J$2:$J$100,MATCH(ROWS($A$9:A10),'Master Stock'!$N$2:$N$100,0)),"") | E10: =IF(D10="","",MAX(0,TODAY()-(IF(ISNUMBER(D10),D10,IFERROR(DATE(2000+VALUE(RIGHT(D10,2)),VALUE(MID(D10,4,2)),VALUE(LEFT(D10,2))),""))))) | G10: =IFERROR(INDEX('Master Stock'!$C$2:$C$100,MATCH(ROWS($G$9:G10),'Master Stock'!$P$2:$P$100,0)),"") | H10: =IFERROR(INDEX('Master Stock'!$D$2:$D$100,MATCH(ROWS($G$9:G10),'Master Stock'!$P$2:$P$100,0)),"") | I10: =IFERROR(INDEX('Master Stock'!$J$2:$J$100,MATCH(ROWS($G$9:G10),'Master Stock'!$P$2:$P$100,0)),"") | J10: =IF(I10="","",MAX(0,TODAY()-(IF(ISNUMBER(I10),I10,IFERROR(DATE(2000+VALUE(RIGHT(I10,2)),VALUE(MID(I10,4,2)),VALUE(LEFT(I10,2))),""))))) | L10: =IFERROR(INDEX('Master Stock'!$C$2:$C$100,AGGREGATE(15,6,(ROW('Master Stock'!$C$2:$C$100)-ROW('Master Stock'!$C$2)+1)/(('Master Stock'!$H$2:$H$100="OCCUPIED")*('Master Stock'!$J$2:$J$100<>"")*('Master Stock'!$K$2:$K$100="")*('Master Stock'!$J$2:$J$100<TODAY()-30)),2)),"") | M10: =IFERROR(INDEX('Master Stock'!$D$2:$D$100,AGGREGATE(15,6,(ROW('Master Stock'!$C$2:$C$100)-ROW('Master Stock'!$C$2)+1)/(('Master Stock'!$H$2:$H$100="OCCUPIED")*('Master Stock'!$J$2:$J$100<>"")*('Master Stock'!$K$2:$K$100="")*('Master Stock'!$J$2:$J$100<TODAY()-30)),2)),"") | N10: =IFERROR(INDEX('Master Stock'!$J$2:$J$100,AGGREGATE(15,6,(ROW('Master Stock'!$C$2:$C$100)-ROW('Master Stock'!$C$2)+1)/(('Master Stock'!$H$2:$H$100="OCCUPIED")*('Master Stock'!$J$2:$J$100<>"")*('Master Stock'!$K$2:$K$100="")*('Master Stock'!$J$2:$J$100<TODAY()-30)),2)),"") | O10: =IF(N10="","",MAX(0,TODAY()-(IF(ISNUMBER(N10),N10,IFERROR(DATE(2000+VALUE(RIGHT(N10,2)),VALUE(MID(N10,4,2)),VALUE(LEFT(N10,2))),"")))))
A11: =IFERROR(INDEX('Master Stock'!$C$2:$C$100,MATCH(ROWS($A$9:A11),'Master Stock'!$N$2:$N$100,0)),"") | B11: =IFERROR(INDEX('Master Stock'!$D$2:$D$100,MATCH(ROWS($A$9:A11),'Master Stock'!$N$2:$N$100,0)),"") | C11: =IFERROR(INDEX('Master Stock'!$B$2:$B$100,MATCH(ROWS($A$9:A11),'Master Stock'!$N$2:$N$100,0)),"") | D11: =IFERROR(INDEX('Master Stock'!$J$2:$J$100,MATCH(ROWS($A$9:A11),'Master Stock'!$N$2:$N$100,0)),"") | E11: =IF(D11="","",MAX(0,TODAY()-(IF(ISNUMBER(D11),D11,IFERROR(DATE(2000+VALUE(RIGHT(D11,2)),VALUE(MID(D11,4,2)),VALUE(LEFT(D11,2))),""))))) | G11: =IFERROR(INDEX('Master Stock'!$C$2:$C$100,MATCH(ROWS($G$9:G11),'Master Stock'!$P$2:$P$100,0)),"") | H11: =IFERROR(INDEX('Master Stock'!$D$2:$D$100,MATCH(ROWS($G$9:G11),'Master Stock'!$P$2:$P$100,0)),"") | I11: =IFERROR(INDEX('Master Stock'!$J$2:$J$100,MATCH(ROWS($G$9:G11),'Master Stock'!$P$2:$P$100,0)),"") | J11: =IF(I11="","",MAX(0,TODAY()-(IF(ISNUMBER(I11),I11,IFERROR(DATE(2000+VALUE(RIGHT(I11,2)),VALUE(MID(I11,4,2)),VALUE(LEFT(I11,2))),""))))) | L11: =IFERROR(INDEX('Master Stock'!$C$2:$C$100,AGGREGATE(15,6,(ROW('Master Stock'!$C$2:$C$100)-ROW('Master Stock'!$C$2)+1)/(('Master Stock'!$H$2:$H$100="OCCUPIED")*('Master Stock'!$J$2:$J$100<>"")*('Master Stock'!$K$2:$K$100="")*('Master Stock'!$J$2:$J$100<TODAY()-30)),3)),"") | M11: =IFERROR(INDEX('Master Stock'!$D$2:$D$100,AGGREGATE(15,6,(ROW('Master Stock'!$C$2:$C$100)-ROW('Master Stock'!$C$2)+1)/(('Master Stock'!$H$2:$H$100="OCCUPIED")*('Master Stock'!$J$2:$J$100<>"")*('Master Stock'!$K$2:$K$100="")*('Master Stock'!$J$2:$J$100<TODAY()-30)),3)),"") | N11: =IFERROR(INDEX('Master Stock'!$J$2:$J$100,AGGREGATE(15,6,(ROW('Master Stock'!$C$2:$C$100)-ROW('Master Stock'!$C$2)+1)/(('Master Stock'!$H$2:$H$100="OCCUPIED")*('Master Stock'!$J$2:$J$100<>"")*('Master Stock'!$K$2:$K$100="")*('Master Stock'!$J$2:$J$100<TODAY()-30)),3)),"") | O11: =IF(N11="","",MAX(0,TODAY()-(IF(ISNUMBER(N11),N11,IFERROR(DATE(2000+VALUE(RIGHT(N11,2)),VALUE(MID(N11,4,2)),VALUE(LEFT(N11,2))),"")))))
A12: =IFERROR(INDEX('Master Stock'!$C$2:$C$100,MATCH(ROWS($A$9:A12),'Master Stock'!$N$2:$N$100,0)),"") | B12: =IFERROR(INDEX('Master Stock'!$D$2:$D$100,MATCH(ROWS($A$9:A12),'Master Stock'!$N$2:$N$100,0)),"") | C12: =IFERROR(INDEX('Master Stock'!$B$2:$B$100,MATCH(ROWS($A$9:A12),'Master Stock'!$N$2:$N$100,0)),"") | D12: =IFERROR(INDEX('Master Stock'!$J$2:$J$100,MATCH(ROWS($A$9:A12),'Master Stock'!$N$2:$N$100,0)),"") | E12: =IF(D12="","",MAX(0,TODAY()-(IF(ISNUMBER(D12),D12,IFERROR(DATE(2000+VALUE(RIGHT(D12,2)),VALUE(MID(D12,4,2)),VALUE(LEFT(D12,2))),""))))) | G12: =IFERROR(INDEX('Master Stock'!$C$2:$C$100,MATCH(ROWS($G$9:G12),'Master Stock'!$P$2:$P$100,0)),"") | H12: =IFERROR(INDEX('Master Stock'!$D$2:$D$100,MATCH(ROWS($G$9:G12),'Master Stock'!$P$2:$P$100,0)),"") | I12: =IFERROR(INDEX('Master Stock'!$J$2:$J$100,MATCH(ROWS($G$9:G12),'Master Stock'!$P$2:$P$100,0)),"") | J12: =IF(I12="","",MAX(0,TODAY()-(IF(ISNUMBER(I12),I12,IFERROR(DATE(2000+VALUE(RIGHT(I12,2)),VALUE(MID(I12,4,2)),VALUE(LEFT(I12,2))),""))))) | L12: =IFERROR(INDEX('Master Stock'!$C$2:$C$100,AGGREGATE(15,6,(ROW('Master Stock'!$C$2:$C$100)-ROW('Master Stock'!$C$2)+1)/(('Master Stock'!$H$2:$H$100="OCCUPIED")*('Master Stock'!$J$2:$J$100<>"")*('Master Stock'!$K$2:$K$100="")*('Master Stock'!$J$2:$J$100<TODAY()-30)),4)),"") | M12: =IFERROR(INDEX('Master Stock'!$D$2:$D$100,AGGREGATE(15,6,(ROW('Master Stock'!$C$2:$C$100)-ROW('Master Stock'!$C$2)+1)/(('Master Stock'!$H$2:$H$100="OCCUPIED")*('Master Stock'!$J$2:$J$100<>"")*('Master Stock'!$K$2:$K$100="")*('Master Stock'!$J$2:$J$100<TODAY()-30)),4)),"") | N12: =IFERROR(INDEX('Master Stock'!$J$2:$J$100,AGGREGATE(15,6,(ROW('Master Stock'!$C$2:$C$100)-ROW('Master Stock'!$C$2)+1)/(('Master Stock'!$H$2:$H$100="OCCUPIED")*('Master Stock'!$J$2:$J$100<>"")*('Master Stock'!$K$2:$K$100="")*('Master Stock'!$J$2:$J$100<TODAY()-30)),4)),"") | O12: =IF(N12="","",MAX(0,TODAY()-(IF(ISNUMBER(N12),N12,IFERROR(DATE(2000+VALUE(RIGHT(N12,2)),VALUE(MID(N12,4,2)),VALUE(LEFT(N12,2))),"")))))
A13: =IFERROR(INDEX('Master Stock'!$C$2:$C$100,MATCH(ROWS($A$9:A13),'Master Stock'!$N$2:$N$100,0)),"") | B13: =IFERROR(INDEX('Master Stock'!$D$2:$D$100,MATCH(ROWS($A$9:A13),'Master Stock'!$N$2:$N$100,0)),"") | C13: =IFERROR(INDEX('Master Stock'!$B$2:$B$100,MATCH(ROWS($A$9:A13),'Master Stock'!$N$2:$N$100,0)),"") | D13: =IFERROR(INDEX('Master Stock'!$J$2:$J$100,MATCH(ROWS($A$9:A13),'Master Stock'!$N$2:$N$100,0)),"") | E13: =IF(D13="","",MAX(0,TODAY()-(IF(ISNUMBER(D13),D13,IFERROR(DATE(2000+VALUE(RIGHT(D13,2)),VALUE(MID(D13,4,2)),VALUE(LEFT(D13,2))),""))))) | G13: =IFERROR(INDEX('Master Stock'!$C$2:$C$100,MATCH(ROWS($G$9:G13),'Master Stock'!$P$2:$P$100,0)),"") | H13: =IFERROR(INDEX('Master Stock'!$D$2:$D$100,MATCH(ROWS($G$9:G13),'Master Stock'!$P$2:$P$100,0)),"") | I13: =IFERROR(INDEX('Master Stock'!$J$2:$J$100,MATCH(ROWS($G$9:G13),'Master Stock'!$P$2:$P$100,0)),"") | J13: =IF(I13="","",MAX(0,TODAY()-(IF(ISNUMBER(I13),I13,IFERROR(DATE(2000+VALUE(RIGHT(I13,2)),VALUE(MID(I13,4,2)),VALUE(LEFT(I13,2))),""))))) | L13: =IFERROR(INDEX('Master Stock'!$C$2:$C$100,AGGREGATE(15,6,(ROW('Master Stock'!$C$2:$C$100)-ROW('Master Stock'!$C$2)+1)/(('Master Stock'!$H$2:$H$100="OCCUPIED")*('Master Stock'!$J$2:$J$100<>"")*('Master Stock'!$K$2:$K$100="")*('Master Stock'!$J$2:$J$100<TODAY()-30)),5)),"") | M13: =IFERROR(INDEX('Master Stock'!$D$2:$D$100,AGGREGATE(15,6,(ROW('Master Stock'!$C$2:$C$100)-ROW('Master Stock'!$C$2)+1)/(('Master Stock'!$H$2:$H$100="OCCUPIED")*('Master Stock'!$J$2:$J$100<>"")*('Master Stock'!$K$2:$K$100="")*('Master Stock'!$J$2:$J$100<TODAY()-30)),5)),"") | N13: =IFERROR(INDEX('Master Stock'!$J$2:$J$100,AGGREGATE(15,6,(ROW('Master Stock'!$C$2:$C$100)-ROW('Master Stock'!$C$2)+1)/(('Master Stock'!$H$2:$H$100="OCCUPIED")*('Master Stock'!$J$2:$J$100<>"")*('Master Stock'!$K$2:$K$100="")*('Master Stock'!$J$2:$J$100<TODAY()-30)),5)),"") | O13: =IF(N13="","",MAX(0,TODAY()-(IF(ISNUMBER(N13),N13,IFERROR(DATE(2000+VALUE(RIGHT(N13,2)),VALUE(MID(N13,4,2)),VALUE(LEFT(N13,2))),"")))))
A14: =IFERROR(INDEX('Master Stock'!$C$2:$C$100,MATCH(ROWS($A$9:A14),'Master Stock'!$N$2:$N$100,0)),"") | B14: =IFERROR(INDEX('Master Stock'!$D$2:$D$100,MATCH(ROWS($A$9:A14),'Master Stock'!$N$2:$N$100,0)),"") | C14: =IFERROR(INDEX('Master Stock'!$B$2:$B$100,MATCH(ROWS($A$9:A14),'Master Stock'!$N$2:$N$100,0)),"") | D14: =IFERROR(INDEX('Master Stock'!$J$2:$J$100,MATCH(ROWS($A$9:A14),'Master Stock'!$N$2:$N$100,0)),"") | E14: =IF(D14="","",MAX(0,TODAY()-(IF(ISNUMBER(D14),D14,IFERROR(DATE(2000+VALUE(RIGHT(D14,2)),VALUE(MID(D14,4,2)),VALUE(LEFT(D14,2))),""))))) | G14: =IFERROR(INDEX('Master Stock'!$C$2:$C$100,MATCH(ROWS($G$9:G14),'Master Stock'!$P$2:$P$100,0)),"") | H14: =IFERROR(INDEX('Master Stock'!$D$2:$D$100,MATCH(ROWS($G$9:G14),'Master Stock'!$P$2:$P$100,0)),"") | I14: =IFERROR(INDEX('Master Stock'!$J$2:$J$100,MATCH(ROWS($G$9:G14),'Master Stock'!$P$2:$P$100,0)),"") | J14: =IF(I14="","",MAX(0,TODAY()-(IF(ISNUMBER(I14),I14,IFERROR(DATE(2000+VALUE(RIGHT(I14,2)),VALUE(MID(I14,4,2)),VALUE(LEFT(I14,2))),""))))) | L14: =IFERROR(INDEX('Master Stock'!$C$2:$C$100,AGGREGATE(15,6,(ROW('Master Stock'!$C$2:$C$100)-ROW('Master Stock'!$C$2)+1)/(('Master Stock'!$H$2:$H$100="OCCUPIED")*('Master Stock'!$J$2:$J$100<>"")*('Master Stock'!$K$2:$K$100="")*('Master Stock'!$J$2:$J$100<TODAY()-30)),6)),"") | M14: =IFERROR(INDEX('Master Stock'!$D$2:$D$100,AGGREGATE(15,6,(ROW('Master Stock'!$C$2:$C$100)-ROW('Master Stock'!$C$2)+1)/(('Master Stock'!$H$2:$H$100="OCCUPIED")*('Master Stock'!$J$2:$J$100<>"")*('Master Stock'!$K$2:$K$100="")*('Master Stock'!$J$2:$J$100<TODAY()-30)),6)),"") | N14: =IFERROR(INDEX('Master Stock'!$J$2:$J$100,AGGREGATE(15,6,(ROW('Master Stock'!$C$2:$C$100)-ROW('Master Stock'!$C$2)+1)/(('Master Stock'!$H$2:$H$100="OCCUPIED")*('Master Stock'!$J$2:$J$100<>"")*('Master Stock'!$K$2:$K$100="")*('Master Stock'!$J$2:$J$100<TODAY()-30)),6)),"") | O14: =IF(N14="","",MAX(0,TODAY()-(IF(ISNUMBER(N14),N14,IFERROR(DATE(2000+VALUE(RIGHT(N14,2)),VALUE(MID(N14,4,2)),VALUE(LEFT(N14,2))),"")))))
A15: =IFERROR(INDEX('Master Stock'!$C$2:$C$100,MATCH(ROWS($A$9:A15),'Master Stock'!$N$2:$N$100,0)),"") | B15: =IFERROR(INDEX('Master Stock'!$D$2:$D$100,MATCH(ROWS($A$9:A15),'Master Stock'!$N$2:$N$100,0)),"") | C15: =IFERROR(INDEX('Master Stock'!$B$2:$B$100,MATCH(ROWS($A$9:A15),'Master Stock'!$N$2:$N$100,0)),"") | D15: =IFERROR(INDEX('Master Stock'!$J$2:$J$100,MATCH(ROWS($A$9:A15),'Master Stock'!$N$2:$N$100,0)),"") | E15: =IF(D15="","",MAX(0,TODAY()-(IF(ISNUMBER(D15),D15,IFERROR(DATE(2000+VALUE(RIGHT(D15,2)),VALUE(MID(D15,4,2)),VALUE(LEFT(D15,2))),""))))) | G15: =IFERROR(INDEX('Master Stock'!$C$2:$C$100,MATCH(ROWS($G$9:G15),'Master Stock'!$P$2:$P$100,0)),"") | H15: =IFERROR(INDEX('Master Stock'!$D$2:$D$100,MATCH(ROWS($G$9:G15),'Master Stock'!$P$2:$P$100,0)),"") | I15: =IFERROR(INDEX('Master Stock'!$J$2:$J$100,MATCH(ROWS($G$9:G15),'Master Stock'!$P$2:$P$100,0)),"") | J15: =IF(I15="","",MAX(0,TODAY()-(IF(ISNUMBER(I15),I15,IFERROR(DATE(2000+VALUE(RIGHT(I15,2)),VALUE(MID(I15,4,2)),VALUE(LEFT(I15,2))),""))))) | L15: =IFERROR(INDEX('Master Stock'!$C$2:$C$100,AGGREGATE(15,6,(ROW('Master Stock'!$C$2:$C$100)-ROW('Master Stock'!$C$2)+1)/(('Master Stock'!$H$2:$H$100="OCCUPIED")*('Master Stock'!$J$2:$J$100<>"")*('Master Stock'!$K$2:$K$100="")*('Master Stock'!$J$2:$J$100<TODAY()-30)),7)),"") | M15: =IFERROR(INDEX('Master Stock'!$D$2:$D$100,AGGREGATE(15,6,(ROW('Master Stock'!$C$2:$C$100)-ROW('Master Stock'!$C$2)+1)/(('Master Stock'!$H$2:$H$100="OCCUPIED")*('Master Stock'!$J$2:$J$100<>"")*('Master Stock'!$K$2:$K$100="")*('Master Stock'!$J$2:$J$100<TODAY()-30)),7)),"") | N15: =IFERROR(INDEX('Master Stock'!$J$2:$J$100,AGGREGATE(15,6,(ROW('Master Stock'!$C$2:$C$100)-ROW('Master Stock'!$C$2)+1)/(('Master Stock'!$H$2:$H$100="OCCUPIED")*('Master Stock'!$J$2:$J$100<>"")*('Master Stock'!$K$2:$K$100="")*('Master Stock'!$J$2:$J$100<TODAY()-30)),7)),"") | O15: =IF(N15="","",MAX(0,TODAY()-(IF(ISNUMBER(N15),N15,IFERROR(DATE(2000+VALUE(RIGHT(N15,2)),VALUE(MID(N15,4,2)),VALUE(LEFT(N15,2))),"")))))
A16: =IFERROR(INDEX('Master Stock'!$C$2:$C$100,MATCH(ROWS($A$9:A16),'Master Stock'!$N$2:$N$100,0)),"") | B16: =IFERROR(INDEX('Master Stock'!$D$2:$D$100,MATCH(ROWS($A$9:A16),'Master Stock'!$N$2:$N$100,0)),"") | C16: =IFERROR(INDEX('Master Stock'!$B$2:$B$100,MATCH(ROWS($A$9:A16),'Master Stock'!$N$2:$N$100,0)),"") | D16: =IFERROR(INDEX('Master Stock'!$J$2:$J$100,MATCH(ROWS($A$9:A16),'Master Stock'!$N$2:$N$100,0)),"") | E16: =IF(D16="","",MAX(0,TODAY()-(IF(ISNUMBER(D16),D16,IFERROR(DATE(2000+VALUE(RIGHT(D16,2)),VALUE(MID(D16,4,2)),VALUE(LEFT(D16,2))),""))))) | G16: =IFERROR(INDEX('Master Stock'!$C$2:$C$100,MATCH(ROWS($G$9:G16),'Master Stock'!$P$2:$P$100,0)),"") | H16: =IFERROR(INDEX('Master Stock'!$D$2:$D$100,MATCH(ROWS($G$9:G16),'Master Stock'!$P$2:$P$100,0)),"") | I16: =IFERROR(INDEX('Master Stock'!$J$2:$J$100,MATCH(ROWS($G$9:G16),'Master Stock'!$P$2:$P$100,0)),"") | J16: =IF(I16="","",MAX(0,TODAY()-(IF(ISNUMBER(I16),I16,IFERROR(DATE(2000+VALUE(RIGHT(I16,2)),VALUE(MID(I16,4,2)),VALUE(LEFT(I16,2))),""))))) | L16: =IFERROR(INDEX('Master Stock'!$C$2:$C$100,AGGREGATE(15,6,(ROW('Master Stock'!$C$2:$C$100)-ROW('Master Stock'!$C$2)+1)/(('Master Stock'!$H$2:$H$100="OCCUPIED")*('Master Stock'!$J$2:$J$100<>"")*('Master Stock'!$K$2:$K$100="")*('Master Stock'!$J$2:$J$100<TODAY()-30)),8)),"") | M16: =IFERROR(INDEX('Master Stock'!$D$2:$D$100,AGGREGATE(15,6,(ROW('Master Stock'!$C$2:$C$100)-ROW('Master Stock'!$C$2)+1)/(('Master Stock'!$H$2:$H$100="OCCUPIED")*('Master Stock'!$J$2:$J$100<>"")*('Master Stock'!$K$2:$K$100="")*('Master Stock'!$J$2:$J$100<TODAY()-30)),8)),"") | N16: =IFERROR(INDEX('Master Stock'!$J$2:$J$100,AGGREGATE(15,6,(ROW('Master Stock'!$C$2:$C$100)-ROW('Master Stock'!$C$2)+1)/(('Master Stock'!$H$2:$H$100="OCCUPIED")*('Master Stock'!$J$2:$J$100<>"")*('Master Stock'!$K$2:$K$100="")*('Master Stock'!$J$2:$J$100<TODAY()-30)),8)),"") | O16: =IF(N16="","",MAX(0,TODAY()-(IF(ISNUMBER(N16),N16,IFERROR(DATE(2000+VALUE(RIGHT(N16,2)),VALUE(MID(N16,4,2)),VALUE(LEFT(N16,2))),"")))))
A17: =IFERROR(INDEX('Master Stock'!$C$2:$C$100,MATCH(ROWS($A$9:A17),'Master Stock'!$N$2:$N$100,0)),"") | B17: =IFERROR(INDEX('Master Stock'!$D$2:$D$100,MATCH(ROWS($A$9:A17),'Master Stock'!$N$2:$N$100,0)),"") | C17: =IFERROR(INDEX('Master Stock'!$B$2:$B$100,MATCH(ROWS($A$9:A17),'Master Stock'!$N$2:$N$100,0)),"") | D17: =IFERROR(INDEX('Master Stock'!$J$2:$J$100,MATCH(ROWS($A$9:A17),'Master Stock'!$N$2:$N$100,0)),"") | E17: =IF(D17="","",MAX(0,TODAY()-(IF(ISNUMBER(D17),D17,IFERROR(DATE(2000+VALUE(RIGHT(D17,2)),VALUE(MID(D17,4,2)),VALUE(LEFT(D17,2))),""))))) | G17: =IFERROR(INDEX('Master Stock'!$C$2:$C$100,MATCH(ROWS($G$9:G17),'Master Stock'!$P$2:$P$100,0)),"") | H17: =IFERROR(INDEX('Master Stock'!$D$2:$D$100,MATCH(ROWS($G$9:G17),'Master Stock'!$P$2:$P$100,0)),"") | I17: =IFERROR(INDEX('Master Stock'!$J$2:$J$100,MATCH(ROWS($G$9:G17),'Master Stock'!$P$2:$P$100,0)),"") | J17: =IF(I17="","",MAX(0,TODAY()-(IF(ISNUMBER(I17),I17,IFERROR(DATE(2000+VALUE(RIGHT(I17,2)),VALUE(MID(I17,4,2)),VALUE(LEFT(I17,2))),""))))) | L17: =IFERROR(INDEX('Master Stock'!$C$2:$C$100,AGGREGATE(15,6,(ROW('Master Stock'!$C$2:$C$100)-ROW('Master Stock'!$C$2)+1)/(('Master Stock'!$H$2:$H$100="OCCUPIED")*('Master Stock'!$J$2:$J$100<>"")*('Master Stock'!$K$2:$K$100="")*('Master Stock'!$J$2:$J$100<TODAY()-30)),9)),"") | M17: =IFERROR(INDEX('Master Stock'!$D$2:$D$100,AGGREGATE(15,6,(ROW('Master Stock'!$C$2:$C$100)-ROW('Master Stock'!$C$2)+1)/(('Master Stock'!$H$2:$H$100="OCCUPIED")*('Master Stock'!$J$2:$J$100<>"")*('Master Stock'!$K$2:$K$100="")*('Master Stock'!$J$2:$J$100<TODAY()-30)),9)),"") | N17: =IFERROR(INDEX('Master Stock'!$J$2:$J$100,AGGREGATE(15,6,(ROW('Master Stock'!$C$2:$C$100)-ROW('Master Stock'!$C$2)+1)/(('Master Stock'!$H$2:$H$100="OCCUPIED")*('Master Stock'!$J$2:$J$100<>"")*('Master Stock'!$K$2:$K$100="")*('Master Stock'!$J$2:$J$100<TODAY()-30)),9)),"") | O17: =IF(N17="","",MAX(0,TODAY()-(IF(ISNUMBER(N17),N17,IFERROR(DATE(2000+VALUE(RIGHT(N17,2)),VALUE(MID(N17,4,2)),VALUE(LEFT(N17,2))),"")))))
A18: =IFERROR(INDEX('Master Stock'!$C$2:$C$100,MATCH(ROWS($A$9:A18),'Master Stock'!$N$2:$N$100,0)),"") | B18: =IFERROR(INDEX('Master Stock'!$D$2:$D$100,MATCH(ROWS($A$9:A18),'Master Stock'!$N$2:$N$100,0)),"") | C18: =IFERROR(INDEX('Master Stock'!$B$2:$B$100,MATCH(ROWS($A$9:A18),'Master Stock'!$N$2:$N$100,0)),"") | D18: =IFERROR(INDEX('Master Stock'!$J$2:$J$100,MATCH(ROWS($A$9:A18),'Master Stock'!$N$2:$N$100,0)),"") | E18: =IF(D18="","",MAX(0,TODAY()-(IF(ISNUMBER(D18),D18,IFERROR(DATE(2000+VALUE(RIGHT(D18,2)),VALUE(MID(D18,4,2)),VALUE(LEFT(D18,2))),""))))) | G18: =IFERROR(INDEX('Master Stock'!$C$2:$C$100,MATCH(ROWS($G$9:G18),'Master Stock'!$P$2:$P$100,0)),"") | H18: =IFERROR(INDEX('Master Stock'!$D$2:$D$100,MATCH(ROWS($G$9:G18),'Master Stock'!$P$2:$P$100,0)),"") | I18: =IFERROR(INDEX('Master Stock'!$J$2:$J$100,MATCH(ROWS($G$9:G18),'Master Stock'!$P$2:$P$100,0)),"") | J18: =IF(I18="","",MAX(0,TODAY()-(IF(ISNUMBER(I18),I18,IFERROR(DATE(2000+VALUE(RIGHT(I18,2)),VALUE(MID(I18,4,2)),VALUE(LEFT(I18,2))),""))))) | L18: =IFERROR(INDEX('Master Stock'!$C$2:$C$100,AGGREGATE(15,6,(ROW('Master Stock'!$C$2:$C$100)-ROW('Master Stock'!$C$2)+1)/(('Master Stock'!$H$2:$H$100="OCCUPIED")*('Master Stock'!$J$2:$J$100<>"")*('Master Stock'!$K$2:$K$100="")*('Master Stock'!$J$2:$J$100<TODAY()-30)),10)),"") | M18: =IFERROR(INDEX('Master Stock'!$D$2:$D$100,AGGREGATE(15,6,(ROW('Master Stock'!$C$2:$C$100)-ROW('Master Stock'!$C$2)+1)/(('Master Stock'!$H$2:$H$100="OCCUPIED")*('Master Stock'!$J$2:$J$100<>"")*('Master Stock'!$K$2:$K$100="")*('Master Stock'!$J$2:$J$100<TODAY()-30)),10)),"") | N18: =IFERROR(INDEX('Master Stock'!$J$2:$J$100,AGGREGATE(15,6,(ROW('Master Stock'!$C$2:$C$100)-ROW('Master Stock'!$C$2)+1)/(('Master Stock'!$H$2:$H$100="OCCUPIED")*('Master Stock'!$J$2:$J$100<>"")*('Master Stock'!$K$2:$K$100="")*('Master Stock'!$J$2:$J$100<TODAY()-30)),10)),"") | O18: =IF(N18="","",MAX(0,TODAY()-(IF(ISNUMBER(N18),N18,IFERROR(DATE(2000+VALUE(RIGHT(N18,2)),VALUE(MID(N18,4,2)),VALUE(LEFT(N18,2))),"")))))
A19: =IFERROR(INDEX('Master Stock'!$C$2:$C$100,MATCH(ROWS($A$9:A19),'Master Stock'!$N$2:$N$100,0)),"") | B19: =IFERROR(INDEX('Master Stock'!$D$2:$D$100,MATCH(ROWS($A$9:A19),'Master Stock'!$N$2:$N$100,0)),"") | C19: =IFERROR(INDEX('Master Stock'!$B$2:$B$100,MATCH(ROWS($A$9:A19),'Master Stock'!$N$2:$N$100,0)),"") | D19: =IFERROR(INDEX('Master Stock'!$J$2:$J$100,MATCH(ROWS($A$9:A19),'Master Stock'!$N$2:$N$100,0)),"") | E19: =IF(D19="","",MAX(0,TODAY()-(IF(ISNUMBER(D19),D19,IFERROR(DATE(2000+VALUE(RIGHT(D19,2)),VALUE(MID(D19,4,2)),VALUE(LEFT(D19,2))),""))))) | G19: =IFERROR(INDEX('Master Stock'!$C$2:$C$100,MATCH(ROWS($G$9:G19),'Master Stock'!$P$2:$P$100,0)),"") | H19: =IFERROR(INDEX('Master Stock'!$D$2:$D$100,MATCH(ROWS($G$9:G19),'Master Stock'!$P$2:$P$100,0)),"") | I19: =IFERROR(INDEX('Master Stock'!$J$2:$J$100,MATCH(ROWS($G$9:G19),'Master Stock'!$P$2:$P$100,0)),"") | J19: =IF(I19="","",MAX(0,TODAY()-(IF(ISNUMBER(I19),I19,IFERROR(DATE(2000+VALUE(RIGHT(I19,2)),VALUE(MID(I19,4,2)),VALUE(LEFT(I19,2))),""))))) | L19: =IFERROR(INDEX('Master Stock'!$C$2:$C$100,AGGREGATE(15,6,(ROW('Master Stock'!$C$2:$C$100)-ROW('Master Stock'!$C$2)+1)/(('Master Stock'!$H$2:$H$100="OCCUPIED")*('Master Stock'!$J$2:$J$100<>"")*('Master Stock'!$K$2:$K$100="")*('Master Stock'!$J$2:$J$100<TODAY()-30)),11)),"") | M19: =IFERROR(INDEX('Master Stock'!$D$2:$D$100,AGGREGATE(15,6,(ROW('Master Stock'!$C$2:$C$100)-ROW('Master Stock'!$C$2)+1)/(('Master Stock'!$H$2:$H$100="OCCUPIED")*('Master Stock'!$J$2:$J$100<>"")*('Master Stock'!$K$2:$K$100="")*('Master Stock'!$J$2:$J$100<TODAY()-30)),11)),"") | N19: =IFERROR(INDEX('Master Stock'!$J$2:$J$100,AGGREGATE(15,6,(ROW('Master Stock'!$C$2:$C$100)-ROW('Master Stock'!$C$2)+1)/(('Master Stock'!$H$2:$H$100="OCCUPIED")*('Master Stock'!$J$2:$J$100<>"")*('Master Stock'!$K$2:$K$100="")*('Master Stock'!$J$2:$J$100<TODAY()-30)),11)),"") | O19: =IF(N19="","",MAX(0,TODAY()-(IF(ISNUMBER(N19),N19,IFERROR(DATE(2000+VALUE(RIGHT(N19,2)),VALUE(MID(N19,4,2)),VALUE(LEFT(N19,2))),"")))))
A20: =IFERROR(INDEX('Master Stock'!$C$2:$C$100,MATCH(ROWS($A$9:A20),'Master Stock'!$N$2:$N$100,0)),"") | B20: =IFERROR(INDEX('Master Stock'!$D$2:$D$100,MATCH(ROWS($A$9:A20),'Master Stock'!$N$2:$N$100,0)),"") | C20: =IFERROR(INDEX('Master Stock'!$B$2:$B$100,MATCH(ROWS($A$9:A20),'Master Stock'!$N$2:$N$100,0)),"") | D20: =IFERROR(INDEX('Master Stock'!$J$2:$J$100,MATCH(ROWS($A$9:A20),'Master Stock'!$N$2:$N$100,0)),"") | E20: =IF(D20="","",MAX(0,TODAY()-(IF(ISNUMBER(D20),D20,IFERROR(DATE(2000+VALUE(RIGHT(D20,2)),VALUE(MID(D20,4,2)),VALUE(LEFT(D20,2))),""))))) | G20: =IFERROR(INDEX('Master Stock'!$C$2:$C$100,MATCH(ROWS($G$9:G20),'Master Stock'!$P$2:$P$100,0)),"") | H20: =IFERROR(INDEX('Master Stock'!$D$2:$D$100,MATCH(ROWS($G$9:G20),'Master Stock'!$P$2:$P$100,0)),"") | I20: =IFERROR(INDEX('Master Stock'!$J$2:$J$100,MATCH(ROWS($G$9:G20),'Master Stock'!$P$2:$P$100,0)),"") | J20: =IF(I20="","",MAX(0,TODAY()-(IF(ISNUMBER(I20),I20,IFERROR(DATE(2000+VALUE(RIGHT(I20,2)),VALUE(MID(I20,4,2)),VALUE(LEFT(I20,2))),""))))) | L20: =IFERROR(INDEX('Master Stock'!$C$2:$C$100,AGGREGATE(15,6,(ROW('Master Stock'!$C$2:$C$100)-ROW('Master Stock'!$C$2)+1)/(('Master Stock'!$H$2:$H$100="OCCUPIED")*('Master Stock'!$J$2:$J$100<>"")*('Master Stock'!$K$2:$K$100="")*('Master Stock'!$J$2:$J$100<TODAY()-30)),12)),"") | M20: =IFERROR(INDEX('Master Stock'!$D$2:$D$100,AGGREGATE(15,6,(ROW('Master Stock'!$C$2:$C$100)-ROW('Master Stock'!$C$2)+1)/(('Master Stock'!$H$2:$H$100="OCCUPIED")*('Master Stock'!$J$2:$J$100<>"")*('Master Stock'!$K$2:$K$100="")*('Master Stock'!$J$2:$J$100<TODAY()-30)),12)),"") | N20: =IFERROR(INDEX('Master Stock'!$J$2:$J$100,AGGREGATE(15,6,(ROW('Master Stock'!$C$2:$C$100)-ROW('Master Stock'!$C$2)+1)/(('Master Stock'!$H$2:$H$100="OCCUPIED")*('Master Stock'!$J$2:$J$100<>"")*('Master Stock'!$K$2:$K$100="")*('Master Stock'!$J$2:$J$100<TODAY()-30)),12)),"") | O20: =IF(N20="","",MAX(0,TODAY()-(IF(ISNUMBER(N20),N20,IFERROR(DATE(2000+VALUE(RIGHT(N20,2)),VALUE(MID(N20,4,2)),VALUE(LEFT(N20,2))),"")))))
A21: =IFERROR(INDEX('Master Stock'!$C$2:$C$100,MATCH(ROWS($A$9:A21),'Master Stock'!$N$2:$N$100,0)),"") | B21: =IFERROR(INDEX('Master Stock'!$D$2:$D$100,MATCH(ROWS($A$9:A21),'Master Stock'!$N$2:$N$100,0)),"") | C21: =IFERROR(INDEX('Master Stock'!$B$2:$B$100,MATCH(ROWS($A$9:A21),'Master Stock'!$N$2:$N$100,0)),"") | D21: =IFERROR(INDEX('Master Stock'!$J$2:$J$100,MATCH(ROWS($A$9:A21),'Master Stock'!$N$2:$N$100,0)),"") | E21: =IF(D21="","",MAX(0,TODAY()-(IF(ISNUMBER(D21),D21,IFERROR(DATE(2000+VALUE(RIGHT(D21,2)),VALUE(MID(D21,4,2)),VALUE(LEFT(D21,2))),""))))) | G21: =IFERROR(INDEX('Master Stock'!$C$2:$C$100,MATCH(ROWS($G$9:G21),'Master Stock'!$P$2:$P$100,0)),"") | H21: =IFERROR(INDEX('Master Stock'!$D$2:$D$100,MATCH(ROWS($G$9:G21),'Master Stock'!$P$2:$P$100,0)),"") | I21: =IFERROR(INDEX('Master Stock'!$J$2:$J$100,MATCH(ROWS($G$9:G21),'Master Stock'!$P$2:$P$100,0)),"") | J21: =IF(I21="","",MAX(0,TODAY()-(IF(ISNUMBER(I21),I21,IFERROR(DATE(2000+VALUE(RIGHT(I21,2)),VALUE(MID(I21,4,2)),VALUE(LEFT(I21,2))),""))))) | L21: =IFERROR(INDEX('Master Stock'!$C$2:$C$100,AGGREGATE(15,6,(ROW('Master Stock'!$C$2:$C$100)-ROW('Master Stock'!$C$2)+1)/(('Master Stock'!$H$2:$H$100="OCCUPIED")*('Master Stock'!$J$2:$J$100<>"")*('Master Stock'!$K$2:$K$100="")*('Master Stock'!$J$2:$J$100<TODAY()-30)),13)),"") | M21: =IFERROR(INDEX('Master Stock'!$D$2:$D$100,AGGREGATE(15,6,(ROW('Master Stock'!$C$2:$C$100)-ROW('Master Stock'!$C$2)+1)/(('Master Stock'!$H$2:$H$100="OCCUPIED")*('Master Stock'!$J$2:$J$100<>"")*('Master Stock'!$K$2:$K$100="")*('Master Stock'!$J$2:$J$100<TODAY()-30)),13)),"") | N21: =IFERROR(INDEX('Master Stock'!$J$2:$J$100,AGGREGATE(15,6,(ROW('Master Stock'!$C$2:$C$100)-ROW('Master Stock'!$C$2)+1)/(('Master Stock'!$H$2:$H$100="OCCUPIED")*('Master Stock'!$J$2:$J$100<>"")*('Master Stock'!$K$2:$K$100="")*('Master Stock'!$J$2:$J$100<TODAY()-30)),13)),"") | O21: =IF(N21="","",MAX(0,TODAY()-(IF(ISNUMBER(N21),N21,IFERROR(DATE(2000+VALUE(RIGHT(N21,2)),VALUE(MID(N21,4,2)),VALUE(LEFT(N21,2))),"")))))
A22: =IFERROR(INDEX('Master Stock'!$C$2:$C$100,MATCH(ROWS($A$9:A22),'Master Stock'!$N$2:$N$100,0)),"") | B22: =IFERROR(INDEX('Master Stock'!$D$2:$D$100,MATCH(ROWS($A$9:A22),'Master Stock'!$N$2:$N$100,0)),"") | C22: =IFERROR(INDEX('Master Stock'!$B$2:$B$100,MATCH(ROWS($A$9:A22),'Master Stock'!$N$2:$N$100,0)),"") | D22: =IFERROR(INDEX('Master Stock'!$J$2:$J$100,MATCH(ROWS($A$9:A22),'Master Stock'!$N$2:$N$100,0)),"") | E22: =IF(D22="","",MAX(0,TODAY()-(IF(ISNUMBER(D22),D22,IFERROR(DATE(2000+VALUE(RIGHT(D22,2)),VALUE(MID(D22,4,2)),VALUE(LEFT(D22,2))),""))))) | G22: =IFERROR(INDEX('Master Stock'!$C$2:$C$100,MATCH(ROWS($G$9:G22),'Master Stock'!$P$2:$P$100,0)),"") | H22: =IFERROR(INDEX('Master Stock'!$D$2:$D$100,MATCH(ROWS($G$9:G22),'Master Stock'!$P$2:$P$100,0)),"") | I22: =IFERROR(INDEX('Master Stock'!$J$2:$J$100,MATCH(ROWS($G$9:G22),'Master Stock'!$P$2:$P$100,0)),"") | J22: =IF(I22="","",MAX(0,TODAY()-(IF(ISNUMBER(I22),I22,IFERROR(DATE(2000+VALUE(RIGHT(I22,2)),VALUE(MID(I22,4,2)),VALUE(LEFT(I22,2))),""))))) | L22: =IFERROR(INDEX('Master Stock'!$C$2:$C$100,AGGREGATE(15,6,(ROW('Master Stock'!$C$2:$C$100)-ROW('Master Stock'!$C$2)+1)/(('Master Stock'!$H$2:$H$100="OCCUPIED")*('Master Stock'!$J$2:$J$100<>"")*('Master Stock'!$K$2:$K$100="")*('Master Stock'!$J$2:$J$100<TODAY()-30)),14)),"") | M22: =IFERROR(INDEX('Master Stock'!$D$2:$D$100,AGGREGATE(15,6,(ROW('Master Stock'!$C$2:$C$100)-ROW('Master Stock'!$C$2)+1)/(('Master Stock'!$H$2:$H$100="OCCUPIED")*('Master Stock'!$J$2:$J$100<>"")*('Master Stock'!$K$2:$K$100="")*('Master Stock'!$J$2:$J$100<TODAY()-30)),14)),"") | N22: =IFERROR(INDEX('Master Stock'!$J$2:$J$100,AGGREGATE(15,6,(ROW('Master Stock'!$C$2:$C$100)-ROW('Master Stock'!$C$2)+1)/(('Master Stock'!$H$2:$H$100="OCCUPIED")*('Master Stock'!$J$2:$J$100<>"")*('Master Stock'!$K$2:$K$100="")*('Master Stock'!$J$2:$J$100<TODAY()-30)),14)),"") | O22: =IF(N22="","",MAX(0,TODAY()-(IF(ISNUMBER(N22),N22,IFERROR(DATE(2000+VALUE(RIGHT(N22,2)),VALUE(MID(N22,4,2)),VALUE(LEFT(N22,2))),"")))))
A23: =IFERROR(INDEX('Master Stock'!$C$2:$C$100,MATCH(ROWS($A$9:A23),'Master Stock'!$N$2:$N$100,0)),"") | B23: =IFERROR(INDEX('Master Stock'!$D$2:$D$100,MATCH(ROWS($A$9:A23),'Master Stock'!$N$2:$N$100,0)),"") | C23: =IFERROR(INDEX('Master Stock'!$B$2:$B$100,MATCH(ROWS($A$9:A23),'Master Stock'!$N$2:$N$100,0)),"") | D23: =IFERROR(INDEX('Master Stock'!$J$2:$J$100,MATCH(ROWS($A$9:A23),'Master Stock'!$N$2:$N$100,0)),"") | E23: =IF(D23="","",MAX(0,TODAY()-(IF(ISNUMBER(D23),D23,IFERROR(DATE(2000+VALUE(RIGHT(D23,2)),VALUE(MID(D23,4,2)),VALUE(LEFT(D23,2))),""))))) | G23: =IFERROR(INDEX('Master Stock'!$C$2:$C$100,MATCH(ROWS($G$9:G23),'Master Stock'!$P$2:$P$100,0)),"") | H23: =IFERROR(INDEX('Master Stock'!$D$2:$D$100,MATCH(ROWS($G$9:G23),'Master Stock'!$P$2:$P$100,0)),"") | I23: =IFERROR(INDEX('Master Stock'!$J$2:$J$100,MATCH(ROWS($G$9:G23),'Master Stock'!$P$2:$P$100,0)),"") | J23: =IF(I23="","",MAX(0,TODAY()-(IF(ISNUMBER(I23),I23,IFERROR(DATE(2000+VALUE(RIGHT(I23,2)),VALUE(MID(I23,4,2)),VALUE(LEFT(I23,2))),""))))) | L23: =IFERROR(INDEX('Master Stock'!$C$2:$C$100,AGGREGATE(15,6,(ROW('Master Stock'!$C$2:$C$100)-ROW('Master Stock'!$C$2)+1)/(('Master Stock'!$H$2:$H$100="OCCUPIED")*('Master Stock'!$J$2:$J$100<>"")*('Master Stock'!$K$2:$K$100="")*('Master Stock'!$J$2:$J$100<TODAY()-30)),15)),"") | M23: =IFERROR(INDEX('Master Stock'!$D$2:$D$100,AGGREGATE(15,6,(ROW('Master Stock'!$C$2:$C$100)-ROW('Master Stock'!$C$2)+1)/(('Master Stock'!$H$2:$H$100="OCCUPIED")*('Master Stock'!$J$2:$J$100<>"")*('Master Stock'!$K$2:$K$100="")*('Master Stock'!$J$2:$J$100<TODAY()-30)),15)),"") | N23: =IFERROR(INDEX('Master Stock'!$J$2:$J$100,AGGREGATE(15,6,(ROW('Master Stock'!$C$2:$C$100)-ROW('Master Stock'!$C$2)+1)/(('Master Stock'!$H$2:$H$100="OCCUPIED")*('Master Stock'!$J$2:$J$100<>"")*('Master Stock'!$K$2:$K$100="")*('Master Stock'!$J$2:$J$100<TODAY()-30)),15)),"") | O23: =IF(N23="","",MAX(0,TODAY()-(IF(ISNUMBER(N23),N23,IFERROR(DATE(2000+VALUE(RIGHT(N23,2)),VALUE(MID(N23,4,2)),VALUE(LEFT(N23,2))),"")))))
A24: =IFERROR(INDEX('Master Stock'!$C$2:$C$100,MATCH(ROWS($A$9:A24),'Master Stock'!$N$2:$N$100,0)),"") | B24: =IFERROR(INDEX('Master Stock'!$D$2:$D$100,MATCH(ROWS($A$9:A24),'Master Stock'!$N$2:$N$100,0)),"") | C24: =IFERROR(INDEX('Master Stock'!$B$2:$B$100,MATCH(ROWS($A$9:A24),'Master Stock'!$N$2:$N$100,0)),"") | D24: =IFERROR(INDEX('Master Stock'!$J$2:$J$100,MATCH(ROWS($A$9:A24),'Master Stock'!$N$2:$N$100,0)),"") | E24: =IF(D24="","",MAX(0,TODAY()-(IF(ISNUMBER(D24),D24,IFERROR(DATE(2000+VALUE(RIGHT(D24,2)),VALUE(MID(D24,4,2)),VALUE(LEFT(D24,2))),""))))) | G24: =IFERROR(INDEX('Master Stock'!$C$2:$C$100,MATCH(ROWS($G$9:G24),'Master Stock'!$P$2:$P$100,0)),"") | H24: =IFERROR(INDEX('Master Stock'!$D$2:$D$100,MATCH(ROWS($G$9:G24),'Master Stock'!$P$2:$P$100,0)),"") | I24: =IFERROR(INDEX('Master Stock'!$J$2:$J$100,MATCH(ROWS($G$9:G24),'Master Stock'!$P$2:$P$100,0)),"") | J24: =IF(I24="","",MAX(0,TODAY()-(IF(ISNUMBER(I24),I24,IFERROR(DATE(2000+VALUE(RIGHT(I24,2)),VALUE(MID(I24,4,2)),VALUE(LEFT(I24,2))),""))))) | L24: =IFERROR(INDEX('Master Stock'!$C$2:$C$100,AGGREGATE(15,6,(ROW('Master Stock'!$C$2:$C$100)-ROW('Master Stock'!$C$2)+1)/(('Master Stock'!$H$2:$H$100="OCCUPIED")*('Master Stock'!$J$2:$J$100<>"")*('Master Stock'!$K$2:$K$100="")*('Master Stock'!$J$2:$J$100<TODAY()-30)),16)),"") | M24: =IFERROR(INDEX('Master Stock'!$D$2:$D$100,AGGREGATE(15,6,(ROW('Master Stock'!$C$2:$C$100)-ROW('Master Stock'!$C$2)+1)/(('Master Stock'!$H$2:$H$100="OCCUPIED")*('Master Stock'!$J$2:$J$100<>"")*('Master Stock'!$K$2:$K$100="")*('Master Stock'!$J$2:$J$100<TODAY()-30)),16)),"") | N24: =IFERROR(INDEX('Master Stock'!$J$2:$J$100,AGGREGATE(15,6,(ROW('Master Stock'!$C$2:$C$100)-ROW('Master Stock'!$C$2)+1)/(('Master Stock'!$H$2:$H$100="OCCUPIED")*('Master Stock'!$J$2:$J$100<>"")*('Master Stock'!$K$2:$K$100="")*('Master Stock'!$J$2:$J$100<TODAY()-30)),16)),"") | O24: =IF(N24="","",MAX(0,TODAY()-(IF(ISNUMBER(N24),N24,IFERROR(DATE(2000+VALUE(RIGHT(N24,2)),VALUE(MID(N24,4,2)),VALUE(LEFT(N24,2))),"")))))
A25: =IFERROR(INDEX('Master Stock'!$C$2:$C$100,MATCH(ROWS($A$9:A25),'Master Stock'!$N$2:$N$100,0)),"") | B25: =IFERROR(INDEX('Master Stock'!$D$2:$D$100,MATCH(ROWS($A$9:A25),'Master Stock'!$N$2:$N$100,0)),"") | C25: =IFERROR(INDEX('Master Stock'!$B$2:$B$100,MATCH(ROWS($A$9:A25),'Master Stock'!$N$2:$N$100,0)),"") | D25: =IFERROR(INDEX('Master Stock'!$J$2:$J$100,MATCH(ROWS($A$9:A25),'Master Stock'!$N$2:$N$100,0)),"") | E25: =IF(D25="","",MAX(0,TODAY()-(IF(ISNUMBER(D25),D25,IFERROR(DATE(2000+VALUE(RIGHT(D25,2)),VALUE(MID(D25,4,2)),VALUE(LEFT(D25,2))),""))))) | G25: =IFERROR(INDEX('Master Stock'!$C$2:$C$100,MATCH(ROWS($G$9:G25),'Master Stock'!$P$2:$P$100,0)),"") | H25: =IFERROR(INDEX('Master Stock'!$D$2:$D$100,MATCH(ROWS($G$9:G25),'Master Stock'!$P$2:$P$100,0)),"") | I25: =IFERROR(INDEX('Master Stock'!$J$2:$J$100,MATCH(ROWS($G$9:G25),'Master Stock'!$P$2:$P$100,0)),"") | J25: =IF(I25="","",MAX(0,TODAY()-(IF(ISNUMBER(I25),I25,IFERROR(DATE(2000+VALUE(RIGHT(I25,2)),VALUE(MID(I25,4,2)),VALUE(LEFT(I25,2))),""))))) | L25: =IFERROR(INDEX('Master Stock'!$C$2:$C$100,AGGREGATE(15,6,(ROW('Master Stock'!$C$2:$C$100)-ROW('Master Stock'!$C$2)+1)/(('Master Stock'!$H$2:$H$100="OCCUPIED")*('Master Stock'!$J$2:$J$100<>"")*('Master Stock'!$K$2:$K$100="")*('Master Stock'!$J$2:$J$100<TODAY()-30)),17)),"") | M25: =IFERROR(INDEX('Master Stock'!$D$2:$D$100,AGGREGATE(15,6,(ROW('Master Stock'!$C$2:$C$100)-ROW('Master Stock'!$C$2)+1)/(('Master Stock'!$H$2:$H$100="OCCUPIED")*('Master Stock'!$J$2:$J$100<>"")*('Master Stock'!$K$2:$K$100="")*('Master Stock'!$J$2:$J$100<TODAY()-30)),17)),"") | N25: =IFERROR(INDEX('Master Stock'!$J$2:$J$100,AGGREGATE(15,6,(ROW('Master Stock'!$C$2:$C$100)-ROW('Master Stock'!$C$2)+1)/(('Master Stock'!$H$2:$H$100="OCCUPIED")*('Master Stock'!$J$2:$J$100<>"")*('Master Stock'!$K$2:$K$100="")*('Master Stock'!$J$2:$J$100<TODAY()-30)),17)),"") | O25: =IF(N25="","",MAX(0,TODAY()-(IF(ISNUMBER(N25),N25,IFERROR(DATE(2000+VALUE(RIGHT(N25,2)),VALUE(MID(N25,4,2)),VALUE(LEFT(N25,2))),"")))))
A26: =IFERROR(INDEX('Master Stock'!$C$2:$C$100,MATCH(ROWS($A$9:A26),'Master Stock'!$N$2:$N$100,0)),"") | B26: =IFERROR(INDEX('Master Stock'!$D$2:$D$100,MATCH(ROWS($A$9:A26),'Master Stock'!$N$2:$N$100,0)),"") | C26: =IFERROR(INDEX('Master Stock'!$B$2:$B$100,MATCH(ROWS($A$9:A26),'Master Stock'!$N$2:$N$100,0)),"") | D26: =IFERROR(INDEX('Master Stock'!$J$2:$J$100,MATCH(ROWS($A$9:A26),'Master Stock'!$N$2:$N$100,0)),"") | E26: =IF(D26="","",MAX(0,TODAY()-(IF(ISNUMBER(D26),D26,IFERROR(DATE(2000+VALUE(RIGHT(D26,2)),VALUE(MID(D26,4,2)),VALUE(LEFT(D26,2))),""))))) | G26: =IFERROR(INDEX('Master Stock'!$C$2:$C$100,MATCH(ROWS($G$9:G26),'Master Stock'!$P$2:$P$100,0)),"") | H26: =IFERROR(INDEX('Master Stock'!$D$2:$D$100,MATCH(ROWS($G$9:G26),'Master Stock'!$P$2:$P$100,0)),"") | I26: =IFERROR(INDEX('Master Stock'!$J$2:$J$100,MATCH(ROWS($G$9:G26),'Master Stock'!$P$2:$P$100,0)),"") | J26: =IF(I26="","",MAX(0,TODAY()-(IF(ISNUMBER(I26),I26,IFERROR(DATE(2000+VALUE(RIGHT(I26,2)),VALUE(MID(I26,4,2)),VALUE(LEFT(I26,2))),""))))) | L26: =IFERROR(INDEX('Master Stock'!$C$2:$C$100,AGGREGATE(15,6,(ROW('Master Stock'!$C$2:$C$100)-ROW('Master Stock'!$C$2)+1)/(('Master Stock'!$H$2:$H$100="OCCUPIED")*('Master Stock'!$J$2:$J$100<>"")*('Master Stock'!$K$2:$K$100="")*('Master Stock'!$J$2:$J$100<TODAY()-30)),18)),"") | M26: =IFERROR(INDEX('Master Stock'!$D$2:$D$100,AGGREGATE(15,6,(ROW('Master Stock'!$C$2:$C$100)-ROW('Master Stock'!$C$2)+1)/(('Master Stock'!$H$2:$H$100="OCCUPIED")*('Master Stock'!$J$2:$J$100<>"")*('Master Stock'!$K$2:$K$100="")*('Master Stock'!$J$2:$J$100<TODAY()-30)),18)),"") | N26: =IFERROR(INDEX('Master Stock'!$J$2:$J$100,AGGREGATE(15,6,(ROW('Master Stock'!$C$2:$C$100)-ROW('Master Stock'!$C$2)+1)/(('Master Stock'!$H$2:$H$100="OCCUPIED")*('Master Stock'!$J$2:$J$100<>"")*('Master Stock'!$K$2:$K$100="")*('Master Stock'!$J$2:$J$100<TODAY()-30)),18)),"") | O26: =IF(N26="","",MAX(0,TODAY()-(IF(ISNUMBER(N26),N26,IFERROR(DATE(2000+VALUE(RIGHT(N26,2)),VALUE(MID(N26,4,2)),VALUE(LEFT(N26,2))),"")))))
A27: =IFERROR(INDEX('Master Stock'!$C$2:$C$100,MATCH(ROWS($A$9:A27),'Master Stock'!$N$2:$N$100,0)),"") | B27: =IFERROR(INDEX('Master Stock'!$D$2:$D$100,MATCH(ROWS($A$9:A27),'Master Stock'!$N$2:$N$100,0)),"") | C27: =IFERROR(INDEX('Master Stock'!$B$2:$B$100,MATCH(ROWS($A$9:A27),'Master Stock'!$N$2:$N$100,0)),"") | D27: =IFERROR(INDEX('Master Stock'!$J$2:$J$100,MATCH(ROWS($A$9:A27),'Master Stock'!$N$2:$N$100,0)),"") | E27: =IF(D27="","",MAX(0,TODAY()-(IF(ISNUMBER(D27),D27,IFERROR(DATE(2000+VALUE(RIGHT(D27,2)),VALUE(MID(D27,4,2)),VALUE(LEFT(D27,2))),""))))) | G27: =IFERROR(INDEX('Master Stock'!$C$2:$C$100,MATCH(ROWS($G$9:G27),'Master Stock'!$P$2:$P$100,0)),"") | H27: =IFERROR(INDEX('Master Stock'!$D$2:$D$100,MATCH(ROWS($G$9:G27),'Master Stock'!$P$2:$P$100,0)),"") | I27: =IFERROR(INDEX('Master Stock'!$J$2:$J$100,MATCH(ROWS($G$9:G27),'Master Stock'!$P$2:$P$100,0)),"") | J27: =IF(I27="","",MAX(0,TODAY()-(IF(ISNUMBER(I27),I27,IFERROR(DATE(2000+VALUE(RIGHT(I27,2)),VALUE(MID(I27,4,2)),VALUE(LEFT(I27,2))),""))))) | L27: =IFERROR(INDEX('Master Stock'!$C$2:$C$100,AGGREGATE(15,6,(ROW('Master Stock'!$C$2:$C$100)-ROW('Master Stock'!$C$2)+1)/(('Master Stock'!$H$2:$H$100="OCCUPIED")*('Master Stock'!$J$2:$J$100<>"")*('Master Stock'!$K$2:$K$100="")*('Master Stock'!$J$2:$J$100<TODAY()-30)),19)),"") | M27: =IFERROR(INDEX('Master Stock'!$D$2:$D$100,AGGREGATE(15,6,(ROW('Master Stock'!$C$2:$C$100)-ROW('Master Stock'!$C$2)+1)/(('Master Stock'!$H$2:$H$100="OCCUPIED")*('Master Stock'!$J$2:$J$100<>"")*('Master Stock'!$K$2:$K$100="")*('Master Stock'!$J$2:$J$100<TODAY()-30)),19)),"") | N27: =IFERROR(INDEX('Master Stock'!$J$2:$J$100,AGGREGATE(15,6,(ROW('Master Stock'!$C$2:$C$100)-ROW('Master Stock'!$C$2)+1)/(('Master Stock'!$H$2:$H$100="OCCUPIED")*('Master Stock'!$J$2:$J$100<>"")*('Master Stock'!$K$2:$K$100="")*('Master Stock'!$J$2:$J$100<TODAY()-30)),19)),"") | O27: =IF(N27="","",MAX(0,TODAY()-(IF(ISNUMBER(N27),N27,IFERROR(DATE(2000+VALUE(RIGHT(N27,2)),VALUE(MID(N27,4,2)),VALUE(LEFT(N27,2))),"")))))
A28: =IFERROR(INDEX('Master Stock'!$C$2:$C$100,MATCH(ROWS($A$9:A28),'Master Stock'!$N$2:$N$100,0)),"") | B28: =IFERROR(INDEX('Master Stock'!$D$2:$D$100,MATCH(ROWS($A$9:A28),'Master Stock'!$N$2:$N$100,0)),"") | C28: =IFERROR(INDEX('Master Stock'!$B$2:$B$100,MATCH(ROWS($A$9:A28),'Master Stock'!$N$2:$N$100,0)),"") | D28: =IFERROR(INDEX('Master Stock'!$J$2:$J$100,MATCH(ROWS($A$9:A28),'Master Stock'!$N$2:$N$100,0)),"") | E28: =IF(D28="","",MAX(0,TODAY()-(IF(ISNUMBER(D28),D28,IFERROR(DATE(2000+VALUE(RIGHT(D28,2)),VALUE(MID(D28,4,2)),VALUE(LEFT(D28,2))),""))))) | G28: =IFERROR(INDEX('Master Stock'!$C$2:$C$100,MATCH(ROWS($G$9:G28),'Master Stock'!$P$2:$P$100,0)),"") | H28: =IFERROR(INDEX('Master Stock'!$D$2:$D$100,MATCH(ROWS($G$9:G28),'Master Stock'!$P$2:$P$100,0)),"") | I28: =IFERROR(INDEX('Master Stock'!$J$2:$J$100,MATCH(ROWS($G$9:G28),'Master Stock'!$P$2:$P$100,0)),"") | J28: =IF(I28="","",MAX(0,TODAY()-(IF(ISNUMBER(I28),I28,IFERROR(DATE(2000+VALUE(RIGHT(I28,2)),VALUE(MID(I28,4,2)),VALUE(LEFT(I28,2))),""))))) | L28: =IFERROR(INDEX('Master Stock'!$C$2:$C$100,AGGREGATE(15,6,(ROW('Master Stock'!$C$2:$C$100)-ROW('Master Stock'!$C$2)+1)/(('Master Stock'!$H$2:$H$100="OCCUPIED")*('Master Stock'!$J$2:$J$100<>"")*('Master Stock'!$K$2:$K$100="")*('Master Stock'!$J$2:$J$100<TODAY()-30)),20)),"") | M28: =IFERROR(INDEX('Master Stock'!$D$2:$D$100,AGGREGATE(15,6,(ROW('Master Stock'!$C$2:$C$100)-ROW('Master Stock'!$C$2)+1)/(('Master Stock'!$H$2:$H$100="OCCUPIED")*('Master Stock'!$J$2:$J$100<>"")*('Master Stock'!$K$2:$K$100="")*('Master Stock'!$J$2:$J$100<TODAY()-30)),20)),"") | N28: =IFERROR(INDEX('Master Stock'!$J$2:$J$100,AGGREGATE(15,6,(ROW('Master Stock'!$C$2:$C$100)-ROW('Master Stock'!$C$2)+1)/(('Master Stock'!$H$2:$H$100="OCCUPIED")*('Master Stock'!$J$2:$J$100<>"")*('Master Stock'!$K$2:$K$100="")*('Master Stock'!$J$2:$J$100<TODAY()-30)),20)),"") | O28: =IF(N28="","",MAX(0,TODAY()-(IF(ISNUMBER(N28),N28,IFERROR(DATE(2000+VALUE(RIGHT(N28,2)),VALUE(MID(N28,4,2)),VALUE(LEFT(N28,2))),"")))))
A29: =IFERROR(INDEX('Master Stock'!$C$2:$C$100,MATCH(ROWS($A$9:A29),'Master Stock'!$N$2:$N$100,0)),"") | B29: =IFERROR(INDEX('Master Stock'!$D$2:$D$100,MATCH(ROWS($A$9:A29),'Master Stock'!$N$2:$N$100,0)),"") | C29: =IFERROR(INDEX('Master Stock'!$B$2:$B$100,MATCH(ROWS($A$9:A29),'Master Stock'!$N$2:$N$100,0)),"") | D29: =IFERROR(INDEX('Master Stock'!$J$2:$J$100,MATCH(ROWS($A$9:A29),'Master Stock'!$N$2:$N$100,0)),"") | E29: =IF(D29="","",MAX(0,TODAY()-(IF(ISNUMBER(D29),D29,IFERROR(DATE(2000+VALUE(RIGHT(D29,2)),VALUE(MID(D29,4,2)),VALUE(LEFT(D29,2))),""))))) | G29: =IFERROR(INDEX('Master Stock'!$C$2:$C$100,MATCH(ROWS($G$9:G29),'Master Stock'!$P$2:$P$100,0)),"") | H29: =IFERROR(INDEX('Master Stock'!$D$2:$D$100,MATCH(ROWS($G$9:G29),'Master Stock'!$P$2:$P$100,0)),"") | I29: =IFERROR(INDEX('Master Stock'!$J$2:$J$100,MATCH(ROWS($G$9:G29),'Master Stock'!$P$2:$P$100,0)),"") | J29: =IF(I29="","",MAX(0,TODAY()-(IF(ISNUMBER(I29),I29,IFERROR(DATE(2000+VALUE(RIGHT(I29,2)),VALUE(MID(I29,4,2)),VALUE(LEFT(I29,2))),""))))) | L29: =IFERROR(INDEX('Master Stock'!$C$2:$C$100,AGGREGATE(15,6,(ROW('Master Stock'!$C$2:$C$100)-ROW('Master Stock'!$C$2)+1)/(('Master Stock'!$H$2:$H$100="OCCUPIED")*('Master Stock'!$J$2:$J$100<>"")*('Master Stock'!$K$2:$K$100="")*('Master Stock'!$J$2:$J$100<TODAY()-30)),21)),"") | M29: =IFERROR(INDEX('Master Stock'!$D$2:$D$100,AGGREGATE(15,6,(ROW('Master Stock'!$C$2:$C$100)-ROW('Master Stock'!$C$2)+1)/(('Master Stock'!$H$2:$H$100="OCCUPIED")*('Master Stock'!$J$2:$J$100<>"")*('Master Stock'!$K$2:$K$100="")*('Master Stock'!$J$2:$J$100<TODAY()-30)),21)),"") | N29: =IFERROR(INDEX('Master Stock'!$J$2:$J$100,AGGREGATE(15,6,(ROW('Master Stock'!$C$2:$C$100)-ROW('Master Stock'!$C$2)+1)/(('Master Stock'!$H$2:$H$100="OCCUPIED")*('Master Stock'!$J$2:$J$100<>"")*('Master Stock'!$K$2:$K$100="")*('Master Stock'!$J$2:$J$100<TODAY()-30)),21)),"") | O29: =IF(N29="","",MAX(0,TODAY()-(IF(ISNUMBER(N29),N29,IFERROR(DATE(2000+VALUE(RIGHT(N29,2)),VALUE(MID(N29,4,2)),VALUE(LEFT(N29,2))),"")))))
A30: =IFERROR(INDEX('Master Stock'!$C$2:$C$100,MATCH(ROWS($A$9:A30),'Master Stock'!$N$2:$N$100,0)),"") | B30: =IFERROR(INDEX('Master Stock'!$D$2:$D$100,MATCH(ROWS($A$9:A30),'Master Stock'!$N$2:$N$100,0)),"") | C30: =IFERROR(INDEX('Master Stock'!$B$2:$B$100,MATCH(ROWS($A$9:A30),'Master Stock'!$N$2:$N$100,0)),"") | D30: =IFERROR(INDEX('Master Stock'!$J$2:$J$100,MATCH(ROWS($A$9:A30),'Master Stock'!$N$2:$N$100,0)),"") | E30: =IF(D30="","",MAX(0,TODAY()-(IF(ISNUMBER(D30),D30,IFERROR(DATE(2000+VALUE(RIGHT(D30,2)),VALUE(MID(D30,4,2)),VALUE(LEFT(D30,2))),""))))) | G30: =IFERROR(INDEX('Master Stock'!$C$2:$C$100,MATCH(ROWS($G$9:G30),'Master Stock'!$P$2:$P$100,0)),"") | H30: =IFERROR(INDEX('Master Stock'!$D$2:$D$100,MATCH(ROWS($G$9:G30),'Master Stock'!$P$2:$P$100,0)),"") | I30: =IFERROR(INDEX('Master Stock'!$J$2:$J$100,MATCH(ROWS($G$9:G30),'Master Stock'!$P$2:$P$100,0)),"") | J30: =IF(I30="","",MAX(0,TODAY()-(IF(ISNUMBER(I30),I30,IFERROR(DATE(2000+VALUE(RIGHT(I30,2)),VALUE(MID(I30,4,2)),VALUE(LEFT(I30,2))),""))))) | L30: =IFERROR(INDEX('Master Stock'!$C$2:$C$100,AGGREGATE(15,6,(ROW('Master Stock'!$C$2:$C$100)-ROW('Master Stock'!$C$2)+1)/(('Master Stock'!$H$2:$H$100="OCCUPIED")*('Master Stock'!$J$2:$J$100<>"")*('Master Stock'!$K$2:$K$100="")*('Master Stock'!$J$2:$J$100<TODAY()-30)),22)),"") | M30: =IFERROR(INDEX('Master Stock'!$D$2:$D$100,AGGREGATE(15,6,(ROW('Master Stock'!$C$2:$C$100)-ROW('Master Stock'!$C$2)+1)/(('Master Stock'!$H$2:$H$100="OCCUPIED")*('Master Stock'!$J$2:$J$100<>"")*('Master Stock'!$K$2:$K$100="")*('Master Stock'!$J$2:$J$100<TODAY()-30)),22)),"") | N30: =IFERROR(INDEX('Master Stock'!$J$2:$J$100,AGGREGATE(15,6,(ROW('Master Stock'!$C$2:$C$100)-ROW('Master Stock'!$C$2)+1)/(('Master Stock'!$H$2:$H$100="OCCUPIED")*('Master Stock'!$J$2:$J$100<>"")*('Master Stock'!$K$2:$K$100="")*('Master Stock'!$J$2:$J$100<TODAY()-30)),22)),"") | O30: =IF(N30="","",MAX(0,TODAY()-(IF(ISNUMBER(N30),N30,IFERROR(DATE(2000+VALUE(RIGHT(N30,2)),VALUE(MID(N30,4,2)),VALUE(LEFT(N30,2))),"")))))
A31: =IFERROR(INDEX('Master Stock'!$C$2:$C$100,MATCH(ROWS($A$9:A31),'Master Stock'!$N$2:$N$100,0)),"") | B31: =IFERROR(INDEX('Master Stock'!$D$2:$D$100,MATCH(ROWS($A$9:A31),'Master Stock'!$N$2:$N$100,0)),"") | C31: =IFERROR(INDEX('Master Stock'!$B$2:$B$100,MATCH(ROWS($A$9:A31),'Master Stock'!$N$2:$N$100,0)),"") | D31: =IFERROR(INDEX('Master Stock'!$J$2:$J$100,MATCH(ROWS($A$9:A31),'Master Stock'!$N$2:$N$100,0)),"") | E31: =IF(D31="","",MAX(0,TODAY()-(IF(ISNUMBER(D31),D31,IFERROR(DATE(2000+VALUE(RIGHT(D31,2)),VALUE(MID(D31,4,2)),VALUE(LEFT(D31,2))),""))))) | G31: =IFERROR(INDEX('Master Stock'!$C$2:$C$100,MATCH(ROWS($G$9:G31),'Master Stock'!$P$2:$P$100,0)),"") | H31: =IFERROR(INDEX('Master Stock'!$D$2:$D$100,MATCH(ROWS($G$9:G31),'Master Stock'!$P$2:$P$100,0)),"") | I31: =IFERROR(INDEX('Master Stock'!$J$2:$J$100,MATCH(ROWS($G$9:G31),'Master Stock'!$P$2:$P$100,0)),"") | J31: =IF(I31="","",MAX(0,TODAY()-(IF(ISNUMBER(I31),I31,IFERROR(DATE(2000+VALUE(RIGHT(I31,2)),VALUE(MID(I31,4,2)),VALUE(LEFT(I31,2))),""))))) | L31: =IFERROR(INDEX('Master Stock'!$C$2:$C$100,AGGREGATE(15,6,(ROW('Master Stock'!$C$2:$C$100)-ROW('Master Stock'!$C$2)+1)/(('Master Stock'!$H$2:$H$100="OCCUPIED")*('Master Stock'!$J$2:$J$100<>"")*('Master Stock'!$K$2:$K$100="")*('Master Stock'!$J$2:$J$100<TODAY()-30)),23)),"") | M31: =IFERROR(INDEX('Master Stock'!$D$2:$D$100,AGGREGATE(15,6,(ROW('Master Stock'!$C$2:$C$100)-ROW('Master Stock'!$C$2)+1)/(('Master Stock'!$H$2:$H$100="OCCUPIED")*('Master Stock'!$J$2:$J$100<>"")*('Master Stock'!$K$2:$K$100="")*('Master Stock'!$J$2:$J$100<TODAY()-30)),23)),"") | N31: =IFERROR(INDEX('Master Stock'!$J$2:$J$100,AGGREGATE(15,6,(ROW('Master Stock'!$C$2:$C$100)-ROW('Master Stock'!$C$2)+1)/(('Master Stock'!$H$2:$H$100="OCCUPIED")*('Master Stock'!$J$2:$J$100<>"")*('Master Stock'!$K$2:$K$100="")*('Master Stock'!$J$2:$J$100<TODAY()-30)),23)),"") | O31: =IF(N31="","",MAX(0,TODAY()-(IF(ISNUMBER(N31),N31,IFERROR(DATE(2000+VALUE(RIGHT(N31,2)),VALUE(MID(N31,4,2)),VALUE(LEFT(N31,2))),"")))))
A32: =IFERROR(INDEX('Master Stock'!$C$2:$C$100,MATCH(ROWS($A$9:A32),'Master Stock'!$N$2:$N$100,0)),"") | B32: =IFERROR(INDEX('Master Stock'!$D$2:$D$100,MATCH(ROWS($A$9:A32),'Master Stock'!$N$2:$N$100,0)),"") | C32: =IFERROR(INDEX('Master Stock'!$B$2:$B$100,MATCH(ROWS($A$9:A32),'Master Stock'!$N$2:$N$100,0)),"") | D32: =IFERROR(INDEX('Master Stock'!$J$2:$J$100,MATCH(ROWS($A$9:A32),'Master Stock'!$N$2:$N$100,0)),"") | E32: =IF(D32="","",MAX(0,TODAY()-(IF(ISNUMBER(D32),D32,IFERROR(DATE(2000+VALUE(RIGHT(D32,2)),VALUE(MID(D32,4,2)),VALUE(LEFT(D32,2))),""))))) | G32: =IFERROR(INDEX('Master Stock'!$C$2:$C$100,MATCH(ROWS($G$9:G32),'Master Stock'!$P$2:$P$100,0)),"") | H32: =IFERROR(INDEX('Master Stock'!$D$2:$D$100,MATCH(ROWS($G$9:G32),'Master Stock'!$P$2:$P$100,0)),"") | I32: =IFERROR(INDEX('Master Stock'!$J$2:$J$100,MATCH(ROWS($G$9:G32),'Master Stock'!$P$2:$P$100,0)),"") | J32: =IF(I32="","",MAX(0,TODAY()-(IF(ISNUMBER(I32),I32,IFERROR(DATE(2000+VALUE(RIGHT(I32,2)),VALUE(MID(I32,4,2)),VALUE(LEFT(I32,2))),""))))) | L32: =IFERROR(INDEX('Master Stock'!$C$2:$C$100,AGGREGATE(15,6,(ROW('Master Stock'!$C$2:$C$100)-ROW('Master Stock'!$C$2)+1)/(('Master Stock'!$H$2:$H$100="OCCUPIED")*('Master Stock'!$J$2:$J$100<>"")*('Master Stock'!$K$2:$K$100="")*('Master Stock'!$J$2:$J$100<TODAY()-30)),24)),"") | M32: =IFERROR(INDEX('Master Stock'!$D$2:$D$100,AGGREGATE(15,6,(ROW('Master Stock'!$C$2:$C$100)-ROW('Master Stock'!$C$2)+1)/(('Master Stock'!$H$2:$H$100="OCCUPIED")*('Master Stock'!$J$2:$J$100<>"")*('Master Stock'!$K$2:$K$100="")*('Master Stock'!$J$2:$J$100<TODAY()-30)),24)),"") | N32: =IFERROR(INDEX('Master Stock'!$J$2:$J$100,AGGREGATE(15,6,(ROW('Master Stock'!$C$2:$C$100)-ROW('Master Stock'!$C$2)+1)/(('Master Stock'!$H$2:$H$100="OCCUPIED")*('Master Stock'!$J$2:$J$100<>"")*('Master Stock'!$K$2:$K$100="")*('Master Stock'!$J$2:$J$100<TODAY()-30)),24)),"") | O32: =IF(N32="","",MAX(0,TODAY()-(IF(ISNUMBER(N32),N32,IFERROR(DATE(2000+VALUE(RIGHT(N32,2)),VALUE(MID(N32,4,2)),VALUE(LEFT(N32,2))),"")))))
A33: =IFERROR(INDEX('Master Stock'!$C$2:$C$100,MATCH(ROWS($A$9:A33),'Master Stock'!$N$2:$N$100,0)),"") | B33: =IFERROR(INDEX('Master Stock'!$D$2:$D$100,MATCH(ROWS($A$9:A33),'Master Stock'!$N$2:$N$100,0)),"") | C33: =IFERROR(INDEX('Master Stock'!$B$2:$B$100,MATCH(ROWS($A$9:A33),'Master Stock'!$N$2:$N$100,0)),"") | D33: =IFERROR(INDEX('Master Stock'!$J$2:$J$100,MATCH(ROWS($A$9:A33),'Master Stock'!$N$2:$N$100,0)),"") | E33: =IF(D33="","",MAX(0,TODAY()-(IF(ISNUMBER(D33),D33,IFERROR(DATE(2000+VALUE(RIGHT(D33,2)),VALUE(MID(D33,4,2)),VALUE(LEFT(D33,2))),""))))) | G33: =IFERROR(INDEX('Master Stock'!$C$2:$C$100,MATCH(ROWS($G$9:G33),'Master Stock'!$P$2:$P$100,0)),"") | H33: =IFERROR(INDEX('Master Stock'!$D$2:$D$100,MATCH(ROWS($G$9:G33),'Master Stock'!$P$2:$P$100,0)),"") | I33: =IFERROR(INDEX('Master Stock'!$J$2:$J$100,MATCH(ROWS($G$9:G33),'Master Stock'!$P$2:$P$100,0)),"") | J33: =IF(I33="","",MAX(0,TODAY()-(IF(ISNUMBER(I33),I33,IFERROR(DATE(2000+VALUE(RIGHT(I33,2)),VALUE(MID(I33,4,2)),VALUE(LEFT(I33,2))),""))))) | L33: =IFERROR(INDEX('Master Stock'!$C$2:$C$100,AGGREGATE(15,6,(ROW('Master Stock'!$C$2:$C$100)-ROW('Master Stock'!$C$2)+1)/(('Master Stock'!$H$2:$H$100="OCCUPIED")*('Master Stock'!$J$2:$J$100<>"")*('Master Stock'!$K$2:$K$100="")*('Master Stock'!$J$2:$J$100<TODAY()-30)),25)),"") | M33: =IFERROR(INDEX('Master Stock'!$D$2:$D$100,AGGREGATE(15,6,(ROW('Master Stock'!$C$2:$C$100)-ROW('Master Stock'!$C$2)+1)/(('Master Stock'!$H$2:$H$100="OCCUPIED")*('Master Stock'!$J$2:$J$100<>"")*('Master Stock'!$K$2:$K$100="")*('Master Stock'!$J$2:$J$100<TODAY()-30)),25)),"") | N33: =IFERROR(INDEX('Master Stock'!$J$2:$J$100,AGGREGATE(15,6,(ROW('Master Stock'!$C$2:$C$100)-ROW('Master Stock'!$C$2)+1)/(('Master Stock'!$H$2:$H$100="OCCUPIED")*('Master Stock'!$J$2:$J$100<>"")*('Master Stock'!$K$2:$K$100="")*('Master Stock'!$J$2:$J$100<TODAY()-30)),25)),"") | O33: =IF(N33="","",MAX(0,TODAY()-(IF(ISNUMBER(N33),N33,IFERROR(DATE(2000+VALUE(RIGHT(N33,2)),VALUE(MID(N33,4,2)),VALUE(LEFT(N33,2))),"")))))
A34: =IFERROR(INDEX('Master Stock'!$C$2:$C$100,MATCH(ROWS($A$9:A34),'Master Stock'!$N$2:$N$100,0)),"") | B34: =IFERROR(INDEX('Master Stock'!$D$2:$D$100,MATCH(ROWS($A$9:A34),'Master Stock'!$N$2:$N$100,0)),"") | C34: =IFERROR(INDEX('Master Stock'!$B$2:$B$100,MATCH(ROWS($A$9:A34),'Master Stock'!$N$2:$N$100,0)),"") | D34: =IFERROR(INDEX('Master Stock'!$J$2:$J$100,MATCH(ROWS($A$9:A34),'Master Stock'!$N$2:$N$100,0)),"") | E34: =IF(D34="","",MAX(0,TODAY()-(IF(ISNUMBER(D34),D34,IFERROR(DATE(2000+VALUE(RIGHT(D34,2)),VALUE(MID(D34,4,2)),VALUE(LEFT(D34,2))),""))))) | G34: =IFERROR(INDEX('Master Stock'!$C$2:$C$100,MATCH(ROWS($G$9:G34),'Master Stock'!$P$2:$P$100,0)),"") | H34: =IFERROR(INDEX('Master Stock'!$D$2:$D$100,MATCH(ROWS($G$9:G34),'Master Stock'!$P$2:$P$100,0)),"") | I34: =IFERROR(INDEX('Master Stock'!$J$2:$J$100,MATCH(ROWS($G$9:G34),'Master Stock'!$P$2:$P$100,0)),"") | J34: =IF(I34="","",MAX(0,TODAY()-(IF(ISNUMBER(I34),I34,IFERROR(DATE(2000+VALUE(RIGHT(I34,2)),VALUE(MID(I34,4,2)),VALUE(LEFT(I34,2))),""))))) | L34: =IFERROR(INDEX('Master Stock'!$C$2:$C$100,AGGREGATE(15,6,(ROW('Master Stock'!$C$2:$C$100)-ROW('Master Stock'!$C$2)+1)/(('Master Stock'!$H$2:$H$100="OCCUPIED")*('Master Stock'!$J$2:$J$100<>"")*('Master Stock'!$K$2:$K$100="")*('Master Stock'!$J$2:$J$100<TODAY()-30)),26)),"") | M34: =IFERROR(INDEX('Master Stock'!$D$2:$D$100,AGGREGATE(15,6,(ROW('Master Stock'!$C$2:$C$100)-ROW('Master Stock'!$C$2)+1)/(('Master Stock'!$H$2:$H$100="OCCUPIED")*('Master Stock'!$J$2:$J$100<>"")*('Master Stock'!$K$2:$K$100="")*('Master Stock'!$J$2:$J$100<TODAY()-30)),26)),"") | N34: =IFERROR(INDEX('Master Stock'!$J$2:$J$100,AGGREGATE(15,6,(ROW('Master Stock'!$C$2:$C$100)-ROW('Master Stock'!$C$2)+1)/(('Master Stock'!$H$2:$H$100="OCCUPIED")*('Master Stock'!$J$2:$J$100<>"")*('Master Stock'!$K$2:$K$100="")*('Master Stock'!$J$2:$J$100<TODAY()-30)),26)),"") | O34: =IF(N34="","",MAX(0,TODAY()-(IF(ISNUMBER(N34),N34,IFERROR(DATE(2000+VALUE(RIGHT(N34,2)),VALUE(MID(N34,4,2)),VALUE(LEFT(N34,2))),"")))))
A35: =IFERROR(INDEX('Master Stock'!$C$2:$C$100,MATCH(ROWS($A$9:A35),'Master Stock'!$N$2:$N$100,0)),"") | B35: =IFERROR(INDEX('Master Stock'!$D$2:$D$100,MATCH(ROWS($A$9:A35),'Master Stock'!$N$2:$N$100,0)),"") | C35: =IFERROR(INDEX('Master Stock'!$B$2:$B$100,MATCH(ROWS($A$9:A35),'Master Stock'!$N$2:$N$100,0)),"") | D35: =IFERROR(INDEX('Master Stock'!$J$2:$J$100,MATCH(ROWS($A$9:A35),'Master Stock'!$N$2:$N$100,0)),"") | E35: =IF(D35="","",MAX(0,TODAY()-(IF(ISNUMBER(D35),D35,IFERROR(DATE(2000+VALUE(RIGHT(D35,2)),VALUE(MID(D35,4,2)),VALUE(LEFT(D35,2))),""))))) | G35: =IFERROR(INDEX('Master Stock'!$C$2:$C$100,MATCH(ROWS($G$9:G35),'Master Stock'!$P$2:$P$100,0)),"") | H35: =IFERROR(INDEX('Master Stock'!$D$2:$D$100,MATCH(ROWS($G$9:G35),'Master Stock'!$P$2:$P$100,0)),"") | I35: =IFERROR(INDEX('Master Stock'!$J$2:$J$100,MATCH(ROWS($G$9:G35),'Master Stock'!$P$2:$P$100,0)),"") | J35: =IF(I35="","",MAX(0,TODAY()-(IF(ISNUMBER(I35),I35,IFERROR(DATE(2000+VALUE(RIGHT(I35,2)),VALUE(MID(I35,4,2)),VALUE(LEFT(I35,2))),""))))) | L35: =IFERROR(INDEX('Master Stock'!$C$2:$C$100,AGGREGATE(15,6,(ROW('Master Stock'!$C$2:$C$100)-ROW('Master Stock'!$C$2)+1)/(('Master Stock'!$H$2:$H$100="OCCUPIED")*('Master Stock'!$J$2:$J$100<>"")*('Master Stock'!$K$2:$K$100="")*('Master Stock'!$J$2:$J$100<TODAY()-30)),27)),"") | M35: =IFERROR(INDEX('Master Stock'!$D$2:$D$100,AGGREGATE(15,6,(ROW('Master Stock'!$C$2:$C$100)-ROW('Master Stock'!$C$2)+1)/(('Master Stock'!$H$2:$H$100="OCCUPIED")*('Master Stock'!$J$2:$J$100<>"")*('Master Stock'!$K$2:$K$100="")*('Master Stock'!$J$2:$J$100<TODAY()-30)),27)),"") | N35: =IFERROR(INDEX('Master Stock'!$J$2:$J$100,AGGREGATE(15,6,(ROW('Master Stock'!$C$2:$C$100)-ROW('Master Stock'!$C$2)+1)/(('Master Stock'!$H$2:$H$100="OCCUPIED")*('Master Stock'!$J$2:$J$100<>"")*('Master Stock'!$K$2:$K$100="")*('Master Stock'!$J$2:$J$100<TODAY()-30)),27)),"") | O35: =IF(N35="","",MAX(0,TODAY()-(IF(ISNUMBER(N35),N35,IFERROR(DATE(2000+VALUE(RIGHT(N35,2)),VALUE(MID(N35,4,2)),VALUE(LEFT(N35,2))),"")))))
A36: =IFERROR(INDEX('Master Stock'!$C$2:$C$100,MATCH(ROWS($A$9:A36),'Master Stock'!$N$2:$N$100,0)),"") | B36: =IFERROR(INDEX('Master Stock'!$D$2:$D$100,MATCH(ROWS($A$9:A36),'Master Stock'!$N$2:$N$100,0)),"") | C36: =IFERROR(INDEX('Master Stock'!$B$2:$B$100,MATCH(ROWS($A$9:A36),'Master Stock'!$N$2:$N$100,0)),"") | D36: =IFERROR(INDEX('Master Stock'!$J$2:$J$100,MATCH(ROWS($A$9:A36),'Master Stock'!$N$2:$N$100,0)),"") | E36: =IF(D36="","",MAX(0,TODAY()-(IF(ISNUMBER(D36),D36,IFERROR(DATE(2000+VALUE(RIGHT(D36,2)),VALUE(MID(D36,4,2)),VALUE(LEFT(D36,2))),""))))) | G36: =IFERROR(INDEX('Master Stock'!$C$2:$C$100,MATCH(ROWS($G$9:G36),'Master Stock'!$P$2:$P$100,0)),"") | H36: =IFERROR(INDEX('Master Stock'!$D$2:$D$100,MATCH(ROWS($G$9:G36),'Master Stock'!$P$2:$P$100,0)),"") | I36: =IFERROR(INDEX('Master Stock'!$J$2:$J$100,MATCH(ROWS($G$9:G36),'Master Stock'!$P$2:$P$100,0)),"") | J36: =IF(I36="","",MAX(0,TODAY()-(IF(ISNUMBER(I36),I36,IFERROR(DATE(2000+VALUE(RIGHT(I36,2)),VALUE(MID(I36,4,2)),VALUE(LEFT(I36,2))),""))))) | L36: =IFERROR(INDEX('Master Stock'!$C$2:$C$100,AGGREGATE(15,6,(ROW('Master Stock'!$C$2:$C$100)-ROW('Master Stock'!$C$2)+1)/(('Master Stock'!$H$2:$H$100="OCCUPIED")*('Master Stock'!$J$2:$J$100<>"")*('Master Stock'!$K$2:$K$100="")*('Master Stock'!$J$2:$J$100<TODAY()-30)),28)),"") | M36: =IFERROR(INDEX('Master Stock'!$D$2:$D$100,AGGREGATE(15,6,(ROW('Master Stock'!$C$2:$C$100)-ROW('Master Stock'!$C$2)+1)/(('Master Stock'!$H$2:$H$100="OCCUPIED")*('Master Stock'!$J$2:$J$100<>"")*('Master Stock'!$K$2:$K$100="")*('Master Stock'!$J$2:$J$100<TODAY()-30)),28)),"") | N36: =IFERROR(INDEX('Master Stock'!$J$2:$J$100,AGGREGATE(15,6,(ROW('Master Stock'!$C$2:$C$100)-ROW('Master Stock'!$C$2)+1)/(('Master Stock'!$H$2:$H$100="OCCUPIED")*('Master Stock'!$J$2:$J$100<>"")*('Master Stock'!$K$2:$K$100="")*('Master Stock'!$J$2:$J$100<TODAY()-30)),28)),"") | O36: =IF(N36="","",MAX(0,TODAY()-(IF(ISNUMBER(N36),N36,IFERROR(DATE(2000+VALUE(RIGHT(N36,2)),VALUE(MID(N36,4,2)),VALUE(LEFT(N36,2))),"")))))
A37: =IFERROR(INDEX('Master Stock'!$C$2:$C$100,MATCH(ROWS($A$9:A37),'Master Stock'!$N$2:$N$100,0)),"") | B37: =IFERROR(INDEX('Master Stock'!$D$2:$D$100,MATCH(ROWS($A$9:A37),'Master Stock'!$N$2:$N$100,0)),"") | C37: =IFERROR(INDEX('Master Stock'!$B$2:$B$100,MATCH(ROWS($A$9:A37),'Master Stock'!$N$2:$N$100,0)),"") | D37: =IFERROR(INDEX('Master Stock'!$J$2:$J$100,MATCH(ROWS($A$9:A37),'Master Stock'!$N$2:$N$100,0)),"") | E37: =IF(D37="","",MAX(0,TODAY()-(IF(ISNUMBER(D37),D37,IFERROR(DATE(2000+VALUE(RIGHT(D37,2)),VALUE(MID(D37,4,2)),VALUE(LEFT(D37,2))),""))))) | G37: =IFERROR(INDEX('Master Stock'!$C$2:$C$100,MATCH(ROWS($G$9:G37),'Master Stock'!$P$2:$P$100,0)),"") | H37: =IFERROR(INDEX('Master Stock'!$D$2:$D$100,MATCH(ROWS($G$9:G37),'Master Stock'!$P$2:$P$100,0)),"") | I37: =IFERROR(INDEX('Master Stock'!$J$2:$J$100,MATCH(ROWS($G$9:G37),'Master Stock'!$P$2:$P$100,0)),"") | J37: =IF(I37="","",MAX(0,TODAY()-(IF(ISNUMBER(I37),I37,IFERROR(DATE(2000+VALUE(RIGHT(I37,2)),VALUE(MID(I37,4,2)),VALUE(LEFT(I37,2))),""))))) | L37: =IFERROR(INDEX('Master Stock'!$C$2:$C$100,AGGREGATE(15,6,(ROW('Master Stock'!$C$2:$C$100)-ROW('Master Stock'!$C$2)+1)/(('Master Stock'!$H$2:$H$100="OCCUPIED")*('Master Stock'!$J$2:$J$100<>"")*('Master Stock'!$K$2:$K$100="")*('Master Stock'!$J$2:$J$100<TODAY()-30)),29)),"") | M37: =IFERROR(INDEX('Master Stock'!$D$2:$D$100,AGGREGATE(15,6,(ROW('Master Stock'!$C$2:$C$100)-ROW('Master Stock'!$C$2)+1)/(('Master Stock'!$H$2:$H$100="OCCUPIED")*('Master Stock'!$J$2:$J$100<>"")*('Master Stock'!$K$2:$K$100="")*('Master Stock'!$J$2:$J$100<TODAY()-30)),29)),"") | N37: =IFERROR(INDEX('Master Stock'!$J$2:$J$100,AGGREGATE(15,6,(ROW('Master Stock'!$C$2:$C$100)-ROW('Master Stock'!$C$2)+1)/(('Master Stock'!$H$2:$H$100="OCCUPIED")*('Master Stock'!$J$2:$J$100<>"")*('Master Stock'!$K$2:$K$100="")*('Master Stock'!$J$2:$J$100<TODAY()-30)),29)),"") | O37: =IF(N37="","",MAX(0,TODAY()-(IF(ISNUMBER(N37),N37,IFERROR(DATE(2000+VALUE(RIGHT(N37,2)),VALUE(MID(N37,4,2)),VALUE(LEFT(N37,2))),"")))))
